Workbook

Sheet 제품군별 SUMMARY
A2: 2026년 국내영업본부 제품군별 판매계획 (더미데이터)
AC6: (단위-대, 백만원)
A7: 담당 | B7: 구분 | C7: 제품군 | D7: 1월 | F7: 2월 | H7: 3월 | J7: 4월 | L7: 5월 | N7: 6월 | P7: 7월 | R7: 8월 | T7: 9월 | V7: 10월 | X7: 11월 | Z7: 12월 | AB7: 연간 합계
D8: 수량 | E8: 금액 | F8: 수량 | G8: 금액 | H8: 수량 | I8: 금액 | J8: 수량 | K8: 금액 | L8: 수량 | M8: 금액 | N8: 수량 | O8: 금액 | P8: 수량 | Q8: 금액 | R8: 수량 | S8: 금액 | T8: 수량 | U8: 금액 | V8: 수량 | W8: 금액 | X8: 수량 | Y8: 금액 | Z8: 수량 | AA8: 금액
A9: 산전 부문 | B9: 모티브 | C9: V-Type(Cell) | D9: =SUMIF(모티브!$BF:$BF,'제품군별 SUMMARY'!$C9,모티브!P:P) | E9: =SUMIF(모티브!$BF:$BF,'제품군별 SUMMARY'!$C9,모티브!Q:Q)/1000000 | F9: =SUMIF(모티브!$BF:$BF,'제품군별 SUMMARY'!$C9,모티브!S:S) | G9: =SUMIF(모티브!$BF:$BF,'제품군별 SUMMARY'!$C9,모티브!T:T)/1000000 | H9: =SUMIF(모티브!$BF:$BF,'제품군별 SUMMARY'!$C9,모티브!V:V) | I9: =SUMIF(모티브!$BF:$BF,'제품군별 SUMMARY'!$C9,모티브!W:W)/1000000 | J9: =SUMIF(모티브!$BF:$BF,'제품군별 SUMMARY'!$C9,모티브!Y:Y) | K9: =SUMIF(모티브!$BF:$BF,'제품군별 SUMMARY'!$C9,모티브!Z:Z)/1000000 | L9: =SUMIF(모티브!$BF:$BF,'제품군별 SUMMARY'!$C9,모티브!AB:AB) | M9: =SUMIF(모티브!$BF:$BF,'제품군별 SUMMARY'!$C9,모티브!AC:AC)/1000000 | N9: =SUMIF(모티브!$BF:$BF,'제품군별 SUMMARY'!$C9,모티브!AE:AE) | O9: =SUMIF(모티브!$BF:$BF,'제품군별 SUMMARY'!$C9,모티브!AF:AF)/1000000 | P9: =SUMIF(모티브!$BF:$BF,'제품군별 SUMMARY'!$C9,모티브!AH:AH) | Q9: =SUMIF(모티브!$BF:$BF,'제품군별 SUMMARY'!$C9,모티브!AI:AI)/1000000 | R9: =SUMIF(모티브!$BF:$BF,'제품군별 SUMMARY'!$C9,모티브!AK:AK) | S9: =SUMIF(모티브!$BF:$BF,'제품군별 SUMMARY'!$C9,모티브!AL:AL)/1000000 | T9: =SUMIF(모티브!$BF:$BF,'제품군별 SUMMARY'!$C9,모티브!AN:AN) | U9: =SUMIF(모티브!$BF:$BF,'제품군별 SUMMARY'!$C9,모티브!AO:AO)/1000000 | V9: =SUMIF(모티브!$BF:$BF,'제품군별 SUMMARY'!$C9,모티브!AQ:AQ) | W9: =SUMIF(모티브!$BF:$BF,'제품군별 SUMMARY'!$C9,모티브!AR:AR)/1000000 | X9: =SUMIF(모티브!$BF:$BF,'제품군별 SUMMARY'!$C9,모티브!AT:AT) | Y9: =SUMIF(모티브!$BF:$BF,'제품군별 SUMMARY'!$C9,모티브!AU:AU)/1000000 | Z9: =SUMIF(모티브!$BF:$BF,'제품군별 SUMMARY'!$C9,모티브!AW:AW) | AA9: =SUMIF(모티브!$BF:$BF,'제품군별 SUMMARY'!$C9,모티브!AX:AX)/1000000
C10: V-Type(Set)/보수 | D10: =SUMIF(모티브!$BF:$BF,'제품군별 SUMMARY'!$C10,모티브!P:P) | E10: =SUMIF(모티브!$BF:$BF,'제품군별 SUMMARY'!$C10,모티브!Q:Q)/1000000 | F10: =SUMIF(모티브!$BF:$BF,'제품군별 SUMMARY'!$C10,모티브!S:S) | G10: =SUMIF(모티브!$BF:$BF,'제품군별 SUMMARY'!$C10,모티브!T:T)/1000000 | H10: =SUMIF(모티브!$BF:$BF,'제품군별 SUMMARY'!$C10,모티브!V:V) | I10: =SUMIF(모티브!$BF:$BF,'제품군별 SUMMARY'!$C10,모티브!W:W)/1000000 | J10: =SUMIF(모티브!$BF:$BF,'제품군별 SUMMARY'!$C10,모티브!Y:Y) | K10: =SUMIF(모티브!$BF:$BF,'제품군별 SUMMARY'!$C10,모티브!Z:Z)/1000000 | L10: =SUMIF(모티브!$BF:$BF,'제품군별 SUMMARY'!$C10,모티브!AB:AB) | M10: =SUMIF(모티브!$BF:$BF,'제품군별 SUMMARY'!$C10,모티브!AC:AC)/1000000 | N10: =SUMIF(모티브!$BF:$BF,'제품군별 SUMMARY'!$C10,모티브!AE:AE) | O10: =SUMIF(모티브!$BF:$BF,'제품군별 SUMMARY'!$C10,모티브!AF:AF)/1000000 | P10: =SUMIF(모티브!$BF:$BF,'제품군별 SUMMARY'!$C10,모티브!AH:AH) | Q10: =SUMIF(모티브!$BF:$BF,'제품군별 SUMMARY'!$C10,모티브!AI:AI)/1000000 | R10: =SUMIF(모티브!$BF:$BF,'제품군별 SUMMARY'!$C10,모티브!AK:AK) | S10: =SUMIF(모티브!$BF:$BF,'제품군별 SUMMARY'!$C10,모티브!AL:AL)/1000000 | T10: =SUMIF(모티브!$BF:$BF,'제품군별 SUMMARY'!$C10,모티브!AN:AN) | U10: =SUMIF(모티브!$BF:$BF,'제품군별 SUMMARY'!$C10,모티브!AO:AO)/1000000 | V10: =SUMIF(모티브!$BF:$BF,'제품군별 SUMMARY'!$C10,모티브!AQ:AQ) | W10: =SUMIF(모티브!$BF:$BF,'제품군별 SUMMARY'!$C10,모티브!AR:AR)/1000000 | X10: =SUMIF(모티브!$BF:$BF,'제품군별 SUMMARY'!$C10,모티브!AT:AT) | Y10: =SUMIF(모티브!$BF:$BF,'제품군별 SUMMARY'!$C10,모티브!AU:AU)/1000000 | Z10: =SUMIF(모티브!$BF:$BF,'제품군별 SUMMARY'!$C10,모티브!AW:AW) | AA10: =SUMIF(모티브!$BF:$BF,'제품군별 SUMMARY'!$C10,모티브!AX:AX)/1000000
C11: 차량용 중형 EXP | D11: =SUMIF(모티브!$BF:$BF,'제품군별 SUMMARY'!$C11,모티브!P:P) | E11: =SUMIF(모티브!$BF:$BF,'제품군별 SUMMARY'!$C11,모티브!Q:Q)/1000000 | F11: =SUMIF(모티브!$BF:$BF,'제품군별 SUMMARY'!$C11,모티브!S:S) | G11: =SUMIF(모티브!$BF:$BF,'제품군별 SUMMARY'!$C11,모티브!T:T)/1000000 | H11: =SUMIF(모티브!$BF:$BF,'제품군별 SUMMARY'!$C11,모티브!V:V) | I11: =SUMIF(모티브!$BF:$BF,'제품군별 SUMMARY'!$C11,모티브!W:W)/1000000 | J11: =SUMIF(모티브!$BF:$BF,'제품군별 SUMMARY'!$C11,모티브!Y:Y) | K11: =SUMIF(모티브!$BF:$BF,'제품군별 SUMMARY'!$C11,모티브!Z:Z)/1000000 | L11: =SUMIF(모티브!$BF:$BF,'제품군별 SUMMARY'!$C11,모티브!AB:AB) | M11: =SUMIF(모티브!$BF:$BF,'제품군별 SUMMARY'!$C11,모티브!AC:AC)/1000000 | N11: =SUMIF(모티브!$BF:$BF,'제품군별 SUMMARY'!$C11,모티브!AE:AE) | O11: =SUMIF(모티브!$BF:$BF,'제품군별 SUMMARY'!$C11,모티브!AF:AF)/1000000 | P11: =SUMIF(모티브!$BF:$BF,'제품군별 SUMMARY'!$C11,모티브!AH:AH) | Q11: =SUMIF(모티브!$BF:$BF,'제품군별 SUMMARY'!$C11,모티브!AI:AI)/1000000 | R11: =SUMIF(모티브!$BF:$BF,'제품군별 SUMMARY'!$C11,모티브!AK:AK) | S11: =SUMIF(모티브!$BF:$BF,'제품군별 SUMMARY'!$C11,모티브!AL:AL)/1000000 | T11: =SUMIF(모티브!$BF:$BF,'제품군별 SUMMARY'!$C11,모티브!AN:AN) | U11: =SUMIF(모티브!$BF:$BF,'제품군별 SUMMARY'!$C11,모티브!AO:AO)/1000000 | V11: =SUMIF(모티브!$BF:$BF,'제품군별 SUMMARY'!$C11,모티브!AQ:AQ) | W11: =SUMIF(모티브!$BF:$BF,'제품군별 SUMMARY'!$C11,모티브!AR:AR)/1000000 | X11: =SUMIF(모티브!$BF:$BF,'제품군별 SUMMARY'!$C11,모티브!AT:AT) | Y11: =SUMIF(모티브!$BF:$BF,'제품군별 SUMMARY'!$C11,모티브!AU:AU)/1000000 | Z11: =SUMIF(모티브!$BF:$BF,'제품군별 SUMMARY'!$C11,모티브!AW:AW) | AA11: =SUMIF(모티브!$BF:$BF,'제품군별 SUMMARY'!$C11,모티브!AX:AX)/1000000
C12: Longest(EB) | D12: =SUMIF(모티브!$BF:$BF,'제품군별 SUMMARY'!$C12,모티브!P:P) | E12: =SUMIF(모티브!$BF:$BF,'제품군별 SUMMARY'!$C12,모티브!Q:Q)/1000000 | F12: =SUMIF(모티브!$BF:$BF,'제품군별 SUMMARY'!$C12,모티브!S:S) | G12: =SUMIF(모티브!$BF:$BF,'제품군별 SUMMARY'!$C12,모티브!T:T)/1000000 | H12: =SUMIF(모티브!$BF:$BF,'제품군별 SUMMARY'!$C12,모티브!V:V) | I12: =SUMIF(모티브!$BF:$BF,'제품군별 SUMMARY'!$C12,모티브!W:W)/1000000 | J12: =SUMIF(모티브!$BF:$BF,'제품군별 SUMMARY'!$C12,모티브!Y:Y) | K12: =SUMIF(모티브!$BF:$BF,'제품군별 SUMMARY'!$C12,모티브!Z:Z)/1000000 | L12: =SUMIF(모티브!$BF:$BF,'제품군별 SUMMARY'!$C12,모티브!AB:AB) | M12: =SUMIF(모티브!$BF:$BF,'제품군별 SUMMARY'!$C12,모티브!AC:AC)/1000000 | N12: =SUMIF(모티브!$BF:$BF,'제품군별 SUMMARY'!$C12,모티브!AE:AE) | O12: =SUMIF(모티브!$BF:$BF,'제품군별 SUMMARY'!$C12,모티브!AF:AF)/1000000 | P12: =SUMIF(모티브!$BF:$BF,'제품군별 SUMMARY'!$C12,모티브!AH:AH) | Q12: =SUMIF(모티브!$BF:$BF,'제품군별 SUMMARY'!$C12,모티브!AI:AI)/1000000 | R12: =SUMIF(모티브!$BF:$BF,'제품군별 SUMMARY'!$C12,모티브!AK:AK) | S12: =SUMIF(모티브!$BF:$BF,'제품군별 SUMMARY'!$C12,모티브!AL:AL)/1000000 | T12: =SUMIF(모티브!$BF:$BF,'제품군별 SUMMARY'!$C12,모티브!AN:AN) | U12: =SUMIF(모티브!$BF:$BF,'제품군별 SUMMARY'!$C12,모티브!AO:AO)/1000000 | V12: =SUMIF(모티브!$BF:$BF,'제품군별 SUMMARY'!$C12,모티브!AQ:AQ) | W12: =SUMIF(모티브!$BF:$BF,'제품군별 SUMMARY'!$C12,모티브!AR:AR)/1000000 | X12: =SUMIF(모티브!$BF:$BF,'제품군별 SUMMARY'!$C12,모티브!AT:AT) | Y12: =SUMIF(모티브!$BF:$BF,'제품군별 SUMMARY'!$C12,모티브!AU:AU)/1000000 | Z12: =SUMIF(모티브!$BF:$BF,'제품군별 SUMMARY'!$C12,모티브!AW:AW) | AA12: =SUMIF(모티브!$BF:$BF,'제품군별 SUMMARY'!$C12,모티브!AX:AX)/1000000
C13: Longest(GC6) | D13: =SUMIF(모티브!$BF:$BF,'제품군별 SUMMARY'!$C13,모티브!P:P) | E13: =SUMIF(모티브!$BF:$BF,'제품군별 SUMMARY'!$C13,모티브!Q:Q)/1000000 | F13: =SUMIF(모티브!$BF:$BF,'제품군별 SUMMARY'!$C13,모티브!S:S) | G13: =SUMIF(모티브!$BF:$BF,'제품군별 SUMMARY'!$C13,모티브!T:T)/1000000 | H13: =SUMIF(모티브!$BF:$BF,'제품군별 SUMMARY'!$C13,모티브!V:V) | I13: =SUMIF(모티브!$BF:$BF,'제품군별 SUMMARY'!$C13,모티브!W:W)/1000000 | J13: =SUMIF(모티브!$BF:$BF,'제품군별 SUMMARY'!$C13,모티브!Y:Y) | K13: =SUMIF(모티브!$BF:$BF,'제품군별 SUMMARY'!$C13,모티브!Z:Z)/1000000 | L13: =SUMIF(모티브!$BF:$BF,'제품군별 SUMMARY'!$C13,모티브!AB:AB) | M13: =SUMIF(모티브!$BF:$BF,'제품군별 SUMMARY'!$C13,모티브!AC:AC)/1000000 | N13: =SUMIF(모티브!$BF:$BF,'제품군별 SUMMARY'!$C13,모티브!AE:AE) | O13: =SUMIF(모티브!$BF:$BF,'제품군별 SUMMARY'!$C13,모티브!AF:AF)/1000000 | P13: =SUMIF(모티브!$BF:$BF,'제품군별 SUMMARY'!$C13,모티브!AH:AH) | Q13: =SUMIF(모티브!$BF:$BF,'제품군별 SUMMARY'!$C13,모티브!AI:AI)/1000000 | R13: =SUMIF(모티브!$BF:$BF,'제품군별 SUMMARY'!$C13,모티브!AK:AK) | S13: =SUMIF(모티브!$BF:$BF,'제품군별 SUMMARY'!$C13,모티브!AL:AL)/1000000 | T13: =SUMIF(모티브!$BF:$BF,'제품군별 SUMMARY'!$C13,모티브!AN:AN) | U13: =SUMIF(모티브!$BF:$BF,'제품군별 SUMMARY'!$C13,모티브!AO:AO)/1000000 | V13: =SUMIF(모티브!$BF:$BF,'제품군별 SUMMARY'!$C13,모티브!AQ:AQ) | W13: =SUMIF(모티브!$BF:$BF,'제품군별 SUMMARY'!$C13,모티브!AR:AR)/1000000 | X13: =SUMIF(모티브!$BF:$BF,'제품군별 SUMMARY'!$C13,모티브!AT:AT) | Y13: =SUMIF(모티브!$BF:$BF,'제품군별 SUMMARY'!$C13,모티브!AU:AU)/1000000 | Z13: =SUMIF(모티브!$BF:$BF,'제품군별 SUMMARY'!$C13,모티브!AW:AW) | AA13: =SUMIF(모티브!$BF:$BF,'제품군별 SUMMARY'!$C13,모티브!AX:AX)/1000000
C14: Longest(GC8) | D14: =SUMIF(모티브!$BF:$BF,'제품군별 SUMMARY'!$C14,모티브!P:P) | E14: =SUMIF(모티브!$BF:$BF,'제품군별 SUMMARY'!$C14,모티브!Q:Q)/1000000 | F14: =SUMIF(모티브!$BF:$BF,'제품군별 SUMMARY'!$C14,모티브!S:S) | G14: =SUMIF(모티브!$BF:$BF,'제품군별 SUMMARY'!$C14,모티브!T:T)/1000000 | H14: =SUMIF(모티브!$BF:$BF,'제품군별 SUMMARY'!$C14,모티브!V:V) | I14: =SUMIF(모티브!$BF:$BF,'제품군별 SUMMARY'!$C14,모티브!W:W)/1000000 | J14: =SUMIF(모티브!$BF:$BF,'제품군별 SUMMARY'!$C14,모티브!Y:Y) | K14: =SUMIF(모티브!$BF:$BF,'제품군별 SUMMARY'!$C14,모티브!Z:Z)/1000000 | L14: =SUMIF(모티브!$BF:$BF,'제품군별 SUMMARY'!$C14,모티브!AB:AB) | M14: =SUMIF(모티브!$BF:$BF,'제품군별 SUMMARY'!$C14,모티브!AC:AC)/1000000 | N14: =SUMIF(모티브!$BF:$BF,'제품군별 SUMMARY'!$C14,모티브!AE:AE) | O14: =SUMIF(모티브!$BF:$BF,'제품군별 SUMMARY'!$C14,모티브!AF:AF)/1000000 | P14: =SUMIF(모티브!$BF:$BF,'제품군별 SUMMARY'!$C14,모티브!AH:AH) | Q14: =SUMIF(모티브!$BF:$BF,'제품군별 SUMMARY'!$C14,모티브!AI:AI)/1000000 | R14: =SUMIF(모티브!$BF:$BF,'제품군별 SUMMARY'!$C14,모티브!AK:AK) | S14: =SUMIF(모티브!$BF:$BF,'제품군별 SUMMARY'!$C14,모티브!AL:AL)/1000000 | T14: =SUMIF(모티브!$BF:$BF,'제품군별 SUMMARY'!$C14,모티브!AN:AN) | U14: =SUMIF(모티브!$BF:$BF,'제품군별 SUMMARY'!$C14,모티브!AO:AO)/1000000 | V14: =SUMIF(모티브!$BF:$BF,'제품군별 SUMMARY'!$C14,모티브!AQ:AQ) | W14: =SUMIF(모티브!$BF:$BF,'제품군별 SUMMARY'!$C14,모티브!AR:AR)/1000000 | X14: =SUMIF(모티브!$BF:$BF,'제품군별 SUMMARY'!$C14,모티브!AT:AT) | Y14: =SUMIF(모티브!$BF:$BF,'제품군별 SUMMARY'!$C14,모티브!AU:AU)/1000000 | Z14: =SUMIF(모티브!$BF:$BF,'제품군별 SUMMARY'!$C14,모티브!AW:AW) | AA14: =SUMIF(모티브!$BF:$BF,'제품군별 SUMMARY'!$C14,모티브!AX:AX)/1000000
C15: 차량용 소형 EXP | D15: =SUMIF(모티브!$BF:$BF,'제품군별 SUMMARY'!$C15,모티브!P:P) | E15: =SUMIF(모티브!$BF:$BF,'제품군별 SUMMARY'!$C15,모티브!Q:Q)/1000000 | F15: =SUMIF(모티브!$BF:$BF,'제품군별 SUMMARY'!$C15,모티브!S:S) | G15: =SUMIF(모티브!$BF:$BF,'제품군별 SUMMARY'!$C15,모티브!T:T)/1000000 | H15: =SUMIF(모티브!$BF:$BF,'제품군별 SUMMARY'!$C15,모티브!V:V) | I15: =SUMIF(모티브!$BF:$BF,'제품군별 SUMMARY'!$C15,모티브!W:W)/1000000 | J15: =SUMIF(모티브!$BF:$BF,'제품군별 SUMMARY'!$C15,모티브!Y:Y) | K15: =SUMIF(모티브!$BF:$BF,'제품군별 SUMMARY'!$C15,모티브!Z:Z)/1000000 | L15: =SUMIF(모티브!$BF:$BF,'제품군별 SUMMARY'!$C15,모티브!AB:AB) | M15: =SUMIF(모티브!$BF:$BF,'제품군별 SUMMARY'!$C15,모티브!AC:AC)/1000000 | N15: =SUMIF(모티브!$BF:$BF,'제품군별 SUMMARY'!$C15,모티브!AE:AE) | O15: =SUMIF(모티브!$BF:$BF,'제품군별 SUMMARY'!$C15,모티브!AF:AF)/1000000 | P15: =SUMIF(모티브!$BF:$BF,'제품군별 SUMMARY'!$C15,모티브!AH:AH) | Q15: =SUMIF(모티브!$BF:$BF,'제품군별 SUMMARY'!$C15,모티브!AI:AI)/1000000 | R15: =SUMIF(모티브!$BF:$BF,'제품군별 SUMMARY'!$C15,모티브!AK:AK) | S15: =SUMIF(모티브!$BF:$BF,'제품군별 SUMMARY'!$C15,모티브!AL:AL)/1000000 | T15: =SUMIF(모티브!$BF:$BF,'제품군별 SUMMARY'!$C15,모티브!AN:AN) | U15: =SUMIF(모티브!$BF:$BF,'제품군별 SUMMARY'!$C15,모티브!AO:AO)/1000000 | V15: =SUMIF(모티브!$BF:$BF,'제품군별 SUMMARY'!$C15,모티브!AQ:AQ) | W15: =SUMIF(모티브!$BF:$BF,'제품군별 SUMMARY'!$C15,모티브!AR:AR)/1000000 | X15: =SUMIF(모티브!$BF:$BF,'제품군별 SUMMARY'!$C15,모티브!AT:AT) | Y15: =SUMIF(모티브!$BF:$BF,'제품군별 SUMMARY'!$C15,모티브!AU:AU)/1000000 | Z15: =SUMIF(모티브!$BF:$BF,'제품군별 SUMMARY'!$C15,모티브!AW:AW) | AA15: =SUMIF(모티브!$BF:$BF,'제품군별 SUMMARY'!$C15,모티브!AX:AX)/1000000
C16: 차량용 대형 EXP | D16: =SUMIF(모티브!$BF:$BF,'제품군별 SUMMARY'!$C16,모티브!P:P) | E16: =SUMIF(모티브!$BF:$BF,'제품군별 SUMMARY'!$C16,모티브!Q:Q)/1000000 | F16: =SUMIF(모티브!$BF:$BF,'제품군별 SUMMARY'!$C16,모티브!S:S) | G16: =SUMIF(모티브!$BF:$BF,'제품군별 SUMMARY'!$C16,모티브!T:T)/1000000 | H16: =SUMIF(모티브!$BF:$BF,'제품군별 SUMMARY'!$C16,모티브!V:V) | I16: =SUMIF(모티브!$BF:$BF,'제품군별 SUMMARY'!$C16,모티브!W:W)/1000000 | J16: =SUMIF(모티브!$BF:$BF,'제품군별 SUMMARY'!$C16,모티브!Y:Y) | K16: =SUMIF(모티브!$BF:$BF,'제품군별 SUMMARY'!$C16,모티브!Z:Z)/1000000 | L16: =SUMIF(모티브!$BF:$BF,'제품군별 SUMMARY'!$C16,모티브!AB:AB) | M16: =SUMIF(모티브!$BF:$BF,'제품군별 SUMMARY'!$C16,모티브!AC:AC)/1000000 | N16: =SUMIF(모티브!$BF:$BF,'제품군별 SUMMARY'!$C16,모티브!AE:AE) | O16: =SUMIF(모티브!$BF:$BF,'제품군별 SUMMARY'!$C16,모티브!AF:AF)/1000000 | P16: =SUMIF(모티브!$BF:$BF,'제품군별 SUMMARY'!$C16,모티브!AH:AH) | Q16: =SUMIF(모티브!$BF:$BF,'제품군별 SUMMARY'!$C16,모티브!AI:AI)/1000000 | R16: =SUMIF(모티브!$BF:$BF,'제품군별 SUMMARY'!$C16,모티브!AK:AK) | S16: =SUMIF(모티브!$BF:$BF,'제품군별 SUMMARY'!$C16,모티브!AL:AL)/1000000 | T16: =SUMIF(모티브!$BF:$BF,'제품군별 SUMMARY'!$C16,모티브!AN:AN) | U16: =SUMIF(모티브!$BF:$BF,'제품군별 SUMMARY'!$C16,모티브!AO:AO)/1000000 | V16: =SUMIF(모티브!$BF:$BF,'제품군별 SUMMARY'!$C16,모티브!AQ:AQ) | W16: =SUMIF(모티브!$BF:$BF,'제품군별 SUMMARY'!$C16,모티브!AR:AR)/1000000 | X16: =SUMIF(모티브!$BF:$BF,'제품군별 SUMMARY'!$C16,모티브!AT:AT) | Y16: =SUMIF(모티브!$BF:$BF,'제품군별 SUMMARY'!$C16,모티브!AU:AU)/1000000 | Z16: =SUMIF(모티브!$BF:$BF,'제품군별 SUMMARY'!$C16,모티브!AW:AW) | AA16: =SUMIF(모티브!$BF:$BF,'제품군별 SUMMARY'!$C16,모티브!AX:AX)/1000000
C17: V-Type(Set)/OEM | D17: =SUMIF(모티브!$BF:$BF,'제품군별 SUMMARY'!$C17,모티브!P:P) | E17: =SUMIF(모티브!$BF:$BF,'제품군별 SUMMARY'!$C17,모티브!Q:Q)/1000000 | F17: =SUMIF(모티브!$BF:$BF,'제품군별 SUMMARY'!$C17,모티브!S:S) | G17: =SUMIF(모티브!$BF:$BF,'제품군별 SUMMARY'!$C17,모티브!T:T)/1000000 | H17: =SUMIF(모티브!$BF:$BF,'제품군별 SUMMARY'!$C17,모티브!V:V) | I17: =SUMIF(모티브!$BF:$BF,'제품군별 SUMMARY'!$C17,모티브!W:W)/1000000 | J17: =SUMIF(모티브!$BF:$BF,'제품군별 SUMMARY'!$C17,모티브!Y:Y) | K17: =SUMIF(모티브!$BF:$BF,'제품군별 SUMMARY'!$C17,모티브!Z:Z)/1000000 | L17: =SUMIF(모티브!$BF:$BF,'제품군별 SUMMARY'!$C17,모티브!AB:AB) | M17: =SUMIF(모티브!$BF:$BF,'제품군별 SUMMARY'!$C17,모티브!AC:AC)/1000000 | N17: =SUMIF(모티브!$BF:$BF,'제품군별 SUMMARY'!$C17,모티브!AE:AE) | O17: =SUMIF(모티브!$BF:$BF,'제품군별 SUMMARY'!$C17,모티브!AF:AF)/1000000 | P17: =SUMIF(모티브!$BF:$BF,'제품군별 SUMMARY'!$C17,모티브!AH:AH) | Q17: =SUMIF(모티브!$BF:$BF,'제품군별 SUMMARY'!$C17,모티브!AI:AI)/1000000 | R17: =SUMIF(모티브!$BF:$BF,'제품군별 SUMMARY'!$C17,모티브!AK:AK) | S17: =SUMIF(모티브!$BF:$BF,'제품군별 SUMMARY'!$C17,모티브!AL:AL)/1000000 | T17: =SUMIF(모티브!$BF:$BF,'제품군별 SUMMARY'!$C17,모티브!AN:AN) | U17: =SUMIF(모티브!$BF:$BF,'제품군별 SUMMARY'!$C17,모티브!AO:AO)/1000000 | V17: =SUMIF(모티브!$BF:$BF,'제품군별 SUMMARY'!$C17,모티브!AQ:AQ) | W17: =SUMIF(모티브!$BF:$BF,'제품군별 SUMMARY'!$C17,모티브!AR:AR)/1000000 | X17: =SUMIF(모티브!$BF:$BF,'제품군별 SUMMARY'!$C17,모티브!AT:AT) | Y17: =SUMIF(모티브!$BF:$BF,'제품군별 SUMMARY'!$C17,모티브!AU:AU)/1000000 | Z17: =SUMIF(모티브!$BF:$BF,'제품군별 SUMMARY'!$C17,모티브!AW:AW) | AA17: =SUMIF(모티브!$BF:$BF,'제품군별 SUMMARY'!$C17,모티브!AX:AX)/1000000
B18: 소계 | D18: =SUM(D9:D17) | E18: =SUM(E9:E17) | F18: =SUM(F9:F17) | G18: =SUM(G9:G17) | H18: =SUM(H9:H17) | I18: =SUM(I9:I17) | J18: =SUM(J9:J17) | K18: =SUM(K9:K17) | ... AA18: =SUM(AA9:AA17)
A19: 산전 부문 | B19: 고정형 | C19: CGS 소형 | D19: =SUMIF(고정형!$BF:$BF,'제품군별 SUMMARY'!$C19,고정형!P:P) | E19: =SUMIF(고정형!$BF:$BF,'제품군별 SUMMARY'!$C19,고정형!Q:Q)/1000000 | F19: =SUMIF(고정형!$BF:$BF,'제품군별 SUMMARY'!$C19,고정형!S:S) | G19: =SUMIF(고정형!$BF:$BF,'제품군별 SUMMARY'!$C19,고정형!T:T)/1000000 | H19: =SUMIF(고정형!$BF:$BF,'제품군별 SUMMARY'!$C19,고정형!V:V) | I19: =SUMIF(고정형!$BF:$BF,'제품군별 SUMMARY'!$C19,고정형!W:W)/1000000 | J19: =SUMIF(고정형!$BF:$BF,'제품군별 SUMMARY'!$C19,고정형!Y:Y) | K19: =SUMIF(고정형!$BF:$BF,'제품군별 SUMMARY'!$C19,고정형!Z:Z)/1000000 | L19: =SUMIF(고정형!$BF:$BF,'제품군별 SUMMARY'!$C19,고정형!AB:AB) | M19: =SUMIF(고정형!$BF:$BF,'제품군별 SUMMARY'!$C19,고정형!AC:AC)/1000000 | N19: =SUMIF(고정형!$BF:$BF,'제품군별 SUMMARY'!$C19,고정형!AE:AE) | O19: =SUMIF(고정형!$BF:$BF,'제품군별 SUMMARY'!$C19,고정형!AF:AF)/1000000 | P19: =SUMIF(고정형!$BF:$BF,'제품군별 SUMMARY'!$C19,고정형!AH:AH) | Q19: =SUMIF(고정형!$BF:$BF,'제품군별 SUMMARY'!$C19,고정형!AI:AI)/1000000 | R19: =SUMIF(고정형!$BF:$BF,'제품군별 SUMMARY'!$C19,고정형!AK:AK) | S19: =SUMIF(고정형!$BF:$BF,'제품군별 SUMMARY'!$C19,고정형!AL:AL)/1000000 | T19: =SUMIF(고정형!$BF:$BF,'제품군별 SUMMARY'!$C19,고정형!AN:AN) | U19: =SUMIF(고정형!$BF:$BF,'제품군별 SUMMARY'!$C19,고정형!AO:AO)/1000000 | V19: =SUMIF(고정형!$BF:$BF,'제품군별 SUMMARY'!$C19,고정형!AQ:AQ) | W19: =SUMIF(고정형!$BF:$BF,'제품군별 SUMMARY'!$C19,고정형!AR:AR)/1000000 | X19: =SUMIF(고정형!$BF:$BF,'제품군별 SUMMARY'!$C19,고정형!AT:AT) | Y19: =SUMIF(고정형!$BF:$BF,'제품군별 SUMMARY'!$C19,고정형!AU:AU)/1000000 | Z19: =SUMIF(고정형!$BF:$BF,'제품군별 SUMMARY'!$C19,고정형!AW:AW) | AA19: =SUMIF(고정형!$BF:$BF,'제품군별 SUMMARY'!$C19,고정형!AX:AX)/1000000
C20: CGS 중형 | D20: =SUMIF(고정형!$BF:$BF,'제품군별 SUMMARY'!$C20,고정형!P:P) | E20: =SUMIF(고정형!$BF:$BF,'제품군별 SUMMARY'!$C20,고정형!Q:Q)/1000000 | F20: =SUMIF(고정형!$BF:$BF,'제품군별 SUMMARY'!$C20,고정형!S:S) | G20: =SUMIF(고정형!$BF:$BF,'제품군별 SUMMARY'!$C20,고정형!T:T)/1000000 | H20: =SUMIF(고정형!$BF:$BF,'제품군별 SUMMARY'!$C20,고정형!V:V) | I20: =SUMIF(고정형!$BF:$BF,'제품군별 SUMMARY'!$C20,고정형!W:W)/1000000 | J20: =SUMIF(고정형!$BF:$BF,'제품군별 SUMMARY'!$C20,고정형!Y:Y) | K20: =SUMIF(고정형!$BF:$BF,'제품군별 SUMMARY'!$C20,고정형!Z:Z)/1000000 | L20: =SUMIF(고정형!$BF:$BF,'제품군별 SUMMARY'!$C20,고정형!AB:AB) | M20: =SUMIF(고정형!$BF:$BF,'제품군별 SUMMARY'!$C20,고정형!AC:AC)/1000000 | N20: =SUMIF(고정형!$BF:$BF,'제품군별 SUMMARY'!$C20,고정형!AE:AE) | O20: =SUMIF(고정형!$BF:$BF,'제품군별 SUMMARY'!$C20,고정형!AF:AF)/1000000 | P20: =SUMIF(고정형!$BF:$BF,'제품군별 SUMMARY'!$C20,고정형!AH:AH) | Q20: =SUMIF(고정형!$BF:$BF,'제품군별 SUMMARY'!$C20,고정형!AI:AI)/1000000 | R20: =SUMIF(고정형!$BF:$BF,'제품군별 SUMMARY'!$C20,고정형!AK:AK) | S20: =SUMIF(고정형!$BF:$BF,'제품군별 SUMMARY'!$C20,고정형!AL:AL)/1000000 | T20: =SUMIF(고정형!$BF:$BF,'제품군별 SUMMARY'!$C20,고정형!AN:AN) | U20: =SUMIF(고정형!$BF:$BF,'제품군별 SUMMARY'!$C20,고정형!AO:AO)/1000000 | V20: =SUMIF(고정형!$BF:$BF,'제품군별 SUMMARY'!$C20,고정형!AQ:AQ) | W20: =SUMIF(고정형!$BF:$BF,'제품군별 SUMMARY'!$C20,고정형!AR:AR)/1000000 | X20: =SUMIF(고정형!$BF:$BF,'제품군별 SUMMARY'!$C20,고정형!AT:AT) | Y20: =SUMIF(고정형!$BF:$BF,'제품군별 SUMMARY'!$C20,고정형!AU:AU)/1000000 | Z20: =SUMIF(고정형!$BF:$BF,'제품군별 SUMMARY'!$C20,고정형!AW:AW) | AA20: =SUMIF(고정형!$BF:$BF,'제품군별 SUMMARY'!$C20,고정형!AX:AX)/1000000
C21: ES 대형 | D21: =SUMIF(고정형!$BF:$BF,'제품군별 SUMMARY'!$C21,고정형!P:P) | E21: =SUMIF(고정형!$BF:$BF,'제품군별 SUMMARY'!$C21,고정형!Q:Q)/1000000 | F21: =SUMIF(고정형!$BF:$BF,'제품군별 SUMMARY'!$C21,고정형!S:S) | G21: =SUMIF(고정형!$BF:$BF,'제품군별 SUMMARY'!$C21,고정형!T:T)/1000000 | H21: =SUMIF(고정형!$BF:$BF,'제품군별 SUMMARY'!$C21,고정형!V:V) | I21: =SUMIF(고정형!$BF:$BF,'제품군별 SUMMARY'!$C21,고정형!W:W)/1000000 | J21: =SUMIF(고정형!$BF:$BF,'제품군별 SUMMARY'!$C21,고정형!Y:Y) | K21: =SUMIF(고정형!$BF:$BF,'제품군별 SUMMARY'!$C21,고정형!Z:Z)/1000000 | L21: =SUMIF(고정형!$BF:$BF,'제품군별 SUMMARY'!$C21,고정형!AB:AB) | M21: =SUMIF(고정형!$BF:$BF,'제품군별 SUMMARY'!$C21,고정형!AC:AC)/1000000 | N21: =SUMIF(고정형!$BF:$BF,'제품군별 SUMMARY'!$C21,고정형!AE:AE) | O21: =SUMIF(고정형!$BF:$BF,'제품군별 SUMMARY'!$C21,고정형!AF:AF)/1000000 | P21: =SUMIF(고정형!$BF:$BF,'제품군별 SUMMARY'!$C21,고정형!AH:AH) | Q21: =SUMIF(고정형!$BF:$BF,'제품군별 SUMMARY'!$C21,고정형!AI:AI)/1000000 | R21: =SUMIF(고정형!$BF:$BF,'제품군별 SUMMARY'!$C21,고정형!AK:AK) | S21: =SUMIF(고정형!$BF:$BF,'제품군별 SUMMARY'!$C21,고정형!AL:AL)/1000000 | T21: =SUMIF(고정형!$BF:$BF,'제품군별 SUMMARY'!$C21,고정형!AN:AN) | U21: =SUMIF(고정형!$BF:$BF,'제품군별 SUMMARY'!$C21,고정형!AO:AO)/1000000 | V21: =SUMIF(고정형!$BF:$BF,'제품군별 SUMMARY'!$C21,고정형!AQ:AQ) | W21: =SUMIF(고정형!$BF:$BF,'제품군별 SUMMARY'!$C21,고정형!AR:AR)/1000000 | X21: =SUMIF(고정형!$BF:$BF,'제품군별 SUMMARY'!$C21,고정형!AT:AT) | Y21: =SUMIF(고정형!$BF:$BF,'제품군별 SUMMARY'!$C21,고정형!AU:AU)/1000000 | Z21: =SUMIF(고정형!$BF:$BF,'제품군별 SUMMARY'!$C21,고정형!AW:AW) | AA21: =SUMIF(고정형!$BF:$BF,'제품군별 SUMMARY'!$C21,고정형!AX:AX)/1000000
C22: ES 소형 | D22: =SUMIF(고정형!$BF:$BF,'제품군별 SUMMARY'!$C22,고정형!P:P) | E22: =SUMIF(고정형!$BF:$BF,'제품군별 SUMMARY'!$C22,고정형!Q:Q)/1000000 | F22: =SUMIF(고정형!$BF:$BF,'제품군별 SUMMARY'!$C22,고정형!S:S) | G22: =SUMIF(고정형!$BF:$BF,'제품군별 SUMMARY'!$C22,고정형!T:T)/1000000 | H22: =SUMIF(고정형!$BF:$BF,'제품군별 SUMMARY'!$C22,고정형!V:V) | I22: =SUMIF(고정형!$BF:$BF,'제품군별 SUMMARY'!$C22,고정형!W:W)/1000000 | J22: =SUMIF(고정형!$BF:$BF,'제품군별 SUMMARY'!$C22,고정형!Y:Y) | K22: =SUMIF(고정형!$BF:$BF,'제품군별 SUMMARY'!$C22,고정형!Z:Z)/1000000 | L22: =SUMIF(고정형!$BF:$BF,'제품군별 SUMMARY'!$C22,고정형!AB:AB) | M22: =SUMIF(고정형!$BF:$BF,'제품군별 SUMMARY'!$C22,고정형!AC:AC)/1000000 | N22: =SUMIF(고정형!$BF:$BF,'제품군별 SUMMARY'!$C22,고정형!AE:AE) | O22: =SUMIF(고정형!$BF:$BF,'제품군별 SUMMARY'!$C22,고정형!AF:AF)/1000000 | P22: =SUMIF(고정형!$BF:$BF,'제품군별 SUMMARY'!$C22,고정형!AH:AH) | Q22: =SUMIF(고정형!$BF:$BF,'제품군별 SUMMARY'!$C22,고정형!AI:AI)/1000000 | R22: =SUMIF(고정형!$BF:$BF,'제품군별 SUMMARY'!$C22,고정형!AK:AK) | S22: =SUMIF(고정형!$BF:$BF,'제품군별 SUMMARY'!$C22,고정형!AL:AL)/1000000 | T22: =SUMIF(고정형!$BF:$BF,'제품군별 SUMMARY'!$C22,고정형!AN:AN) | U22: =SUMIF(고정형!$BF:$BF,'제품군별 SUMMARY'!$C22,고정형!AO:AO)/1000000 | V22: =SUMIF(고정형!$BF:$BF,'제품군별 SUMMARY'!$C22,고정형!AQ:AQ) | W22: =SUMIF(고정형!$BF:$BF,'제품군별 SUMMARY'!$C22,고정형!AR:AR)/1000000 | X22: =SUMIF(고정형!$BF:$BF,'제품군별 SUMMARY'!$C22,고정형!AT:AT) | Y22: =SUMIF(고정형!$BF:$BF,'제품군별 SUMMARY'!$C22,고정형!AU:AU)/1000000 | Z22: =SUMIF(고정형!$BF:$BF,'제품군별 SUMMARY'!$C22,고정형!AW:AW) | AA22: =SUMIF(고정형!$BF:$BF,'제품군별 SUMMARY'!$C22,고정형!AX:AX)/1000000
C23: ES 중형 | D23: =SUMIF(고정형!$BF:$BF,'제품군별 SUMMARY'!$C23,고정형!P:P) | E23: =SUMIF(고정형!$BF:$BF,'제품군별 SUMMARY'!$C23,고정형!Q:Q)/1000000 | F23: =SUMIF(고정형!$BF:$BF,'제품군별 SUMMARY'!$C23,고정형!S:S) | G23: =SUMIF(고정형!$BF:$BF,'제품군별 SUMMARY'!$C23,고정형!T:T)/1000000 | H23: =SUMIF(고정형!$BF:$BF,'제품군별 SUMMARY'!$C23,고정형!V:V) | I23: =SUMIF(고정형!$BF:$BF,'제품군별 SUMMARY'!$C23,고정형!W:W)/1000000 | J23: =SUMIF(고정형!$BF:$BF,'제품군별 SUMMARY'!$C23,고정형!Y:Y) | K23: =SUMIF(고정형!$BF:$BF,'제품군별 SUMMARY'!$C23,고정형!Z:Z)/1000000 | L23: =SUMIF(고정형!$BF:$BF,'제품군별 SUMMARY'!$C23,고정형!AB:AB) | M23: =SUMIF(고정형!$BF:$BF,'제품군별 SUMMARY'!$C23,고정형!AC:AC)/1000000 | N23: =SUMIF(고정형!$BF:$BF,'제품군별 SUMMARY'!$C23,고정형!AE:AE) | O23: =SUMIF(고정형!$BF:$BF,'제품군별 SUMMARY'!$C23,고정형!AF:AF)/1000000 | P23: =SUMIF(고정형!$BF:$BF,'제품군별 SUMMARY'!$C23,고정형!AH:AH) | Q23: =SUMIF(고정형!$BF:$BF,'제품군별 SUMMARY'!$C23,고정형!AI:AI)/1000000 | R23: =SUMIF(고정형!$BF:$BF,'제품군별 SUMMARY'!$C23,고정형!AK:AK) | S23: =SUMIF(고정형!$BF:$BF,'제품군별 SUMMARY'!$C23,고정형!AL:AL)/1000000 | T23: =SUMIF(고정형!$BF:$BF,'제품군별 SUMMARY'!$C23,고정형!AN:AN) | U23: =SUMIF(고정형!$BF:$BF,'제품군별 SUMMARY'!$C23,고정형!AO:AO)/1000000 | V23: =SUMIF(고정형!$BF:$BF,'제품군별 SUMMARY'!$C23,고정형!AQ:AQ) | W23: =SUMIF(고정형!$BF:$BF,'제품군별 SUMMARY'!$C23,고정형!AR:AR)/1000000 | X23: =SUMIF(고정형!$BF:$BF,'제품군별 SUMMARY'!$C23,고정형!AT:AT) | Y23: =SUMIF(고정형!$BF:$BF,'제품군별 SUMMARY'!$C23,고정형!AU:AU)/1000000 | Z23: =SUMIF(고정형!$BF:$BF,'제품군별 SUMMARY'!$C23,고정형!AW:AW) | AA23: =SUMIF(고정형!$BF:$BF,'제품군별 SUMMARY'!$C23,고정형!AX:AX)/1000000
C24: GSL 대형 | D24: =SUMIF(고정형!$BF:$BF,'제품군별 SUMMARY'!$C24,고정형!P:P) | E24: =SUMIF(고정형!$BF:$BF,'제품군별 SUMMARY'!$C24,고정형!Q:Q)/1000000 | F24: =SUMIF(고정형!$BF:$BF,'제품군별 SUMMARY'!$C24,고정형!S:S) | G24: =SUMIF(고정형!$BF:$BF,'제품군별 SUMMARY'!$C24,고정형!T:T)/1000000 | H24: =SUMIF(고정형!$BF:$BF,'제품군별 SUMMARY'!$C24,고정형!V:V) | I24: =SUMIF(고정형!$BF:$BF,'제품군별 SUMMARY'!$C24,고정형!W:W)/1000000 | J24: =SUMIF(고정형!$BF:$BF,'제품군별 SUMMARY'!$C24,고정형!Y:Y) | K24: =SUMIF(고정형!$BF:$BF,'제품군별 SUMMARY'!$C24,고정형!Z:Z)/1000000 | L24: =SUMIF(고정형!$BF:$BF,'제품군별 SUMMARY'!$C24,고정형!AB:AB) | M24: =SUMIF(고정형!$BF:$BF,'제품군별 SUMMARY'!$C24,고정형!AC:AC)/1000000 | N24: =SUMIF(고정형!$BF:$BF,'제품군별 SUMMARY'!$C24,고정형!AE:AE) | O24: =SUMIF(고정형!$BF:$BF,'제품군별 SUMMARY'!$C24,고정형!AF:AF)/1000000 | P24: =SUMIF(고정형!$BF:$BF,'제품군별 SUMMARY'!$C24,고정형!AH:AH) | Q24: =SUMIF(고정형!$BF:$BF,'제품군별 SUMMARY'!$C24,고정형!AI:AI)/1000000 | R24: =SUMIF(고정형!$BF:$BF,'제품군별 SUMMARY'!$C24,고정형!AK:AK) | S24: =SUMIF(고정형!$BF:$BF,'제품군별 SUMMARY'!$C24,고정형!AL:AL)/1000000 | T24: =SUMIF(고정형!$BF:$BF,'제품군별 SUMMARY'!$C24,고정형!AN:AN) | U24: =SUMIF(고정형!$BF:$BF,'제품군별 SUMMARY'!$C24,고정형!AO:AO)/1000000 | V24: =SUMIF(고정형!$BF:$BF,'제품군별 SUMMARY'!$C24,고정형!AQ:AQ) | W24: =SUMIF(고정형!$BF:$BF,'제품군별 SUMMARY'!$C24,고정형!AR:AR)/1000000 | X24: =SUMIF(고정형!$BF:$BF,'제품군별 SUMMARY'!$C24,고정형!AT:AT) | Y24: =SUMIF(고정형!$BF:$BF,'제품군별 SUMMARY'!$C24,고정형!AU:AU)/1000000 | Z24: =SUMIF(고정형!$BF:$BF,'제품군별 SUMMARY'!$C24,고정형!AW:AW) | AA24: =SUMIF(고정형!$BF:$BF,'제품군별 SUMMARY'!$C24,고정형!AX:AX)/1000000
C25: GSL 소형 | D25: =SUMIF(고정형!$BF:$BF,'제품군별 SUMMARY'!$C25,고정형!P:P) | E25: =SUMIF(고정형!$BF:$BF,'제품군별 SUMMARY'!$C25,고정형!Q:Q)/1000000 | F25: =SUMIF(고정형!$BF:$BF,'제품군별 SUMMARY'!$C25,고정형!S:S) | G25: =SUMIF(고정형!$BF:$BF,'제품군별 SUMMARY'!$C25,고정형!T:T)/1000000 | H25: =SUMIF(고정형!$BF:$BF,'제품군별 SUMMARY'!$C25,고정형!V:V) | I25: =SUMIF(고정형!$BF:$BF,'제품군별 SUMMARY'!$C25,고정형!W:W)/1000000 | J25: =SUMIF(고정형!$BF:$BF,'제품군별 SUMMARY'!$C25,고정형!Y:Y) | K25: =SUMIF(고정형!$BF:$BF,'제품군별 SUMMARY'!$C25,고정형!Z:Z)/1000000 | L25: =SUMIF(고정형!$BF:$BF,'제품군별 SUMMARY'!$C25,고정형!AB:AB) | M25: =SUMIF(고정형!$BF:$BF,'제품군별 SUMMARY'!$C25,고정형!AC:AC)/1000000 | N25: =SUMIF(고정형!$BF:$BF,'제품군별 SUMMARY'!$C25,고정형!AE:AE) | O25: =SUMIF(고정형!$BF:$BF,'제품군별 SUMMARY'!$C25,고정형!AF:AF)/1000000 | P25: =SUMIF(고정형!$BF:$BF,'제품군별 SUMMARY'!$C25,고정형!AH:AH) | Q25: =SUMIF(고정형!$BF:$BF,'제품군별 SUMMARY'!$C25,고정형!AI:AI)/1000000 | R25: =SUMIF(고정형!$BF:$BF,'제품군별 SUMMARY'!$C25,고정형!AK:AK) | S25: =SUMIF(고정형!$BF:$BF,'제품군별 SUMMARY'!$C25,고정형!AL:AL)/1000000 | T25: =SUMIF(고정형!$BF:$BF,'제품군별 SUMMARY'!$C25,고정형!AN:AN) | U25: =SUMIF(고정형!$BF:$BF,'제품군별 SUMMARY'!$C25,고정형!AO:AO)/1000000 | V25: =SUMIF(고정형!$BF:$BF,'제품군별 SUMMARY'!$C25,고정형!AQ:AQ) | W25: =SUMIF(고정형!$BF:$BF,'제품군별 SUMMARY'!$C25,고정형!AR:AR)/1000000 | X25: =SUMIF(고정형!$BF:$BF,'제품군별 SUMMARY'!$C25,고정형!AT:AT) | Y25: =SUMIF(고정형!$BF:$BF,'제품군별 SUMMARY'!$C25,고정형!AU:AU)/1000000 | Z25: =SUMIF(고정형!$BF:$BF,'제품군별 SUMMARY'!$C25,고정형!AW:AW) | AA25: =SUMIF(고정형!$BF:$BF,'제품군별 SUMMARY'!$C25,고정형!AX:AX)/1000000
C26: GSL 중형 | D26: =SUMIF(고정형!$BF:$BF,'제품군별 SUMMARY'!$C26,고정형!P:P) | E26: =SUMIF(고정형!$BF:$BF,'제품군별 SUMMARY'!$C26,고정형!Q:Q)/1000000 | F26: =SUMIF(고정형!$BF:$BF,'제품군별 SUMMARY'!$C26,고정형!S:S) | G26: =SUMIF(고정형!$BF:$BF,'제품군별 SUMMARY'!$C26,고정형!T:T)/1000000 | H26: =SUMIF(고정형!$BF:$BF,'제품군별 SUMMARY'!$C26,고정형!V:V) | I26: =SUMIF(고정형!$BF:$BF,'제품군별 SUMMARY'!$C26,고정형!W:W)/1000000 | J26: =SUMIF(고정형!$BF:$BF,'제품군별 SUMMARY'!$C26,고정형!Y:Y) | K26: =SUMIF(고정형!$BF:$BF,'제품군별 SUMMARY'!$C26,고정형!Z:Z)/1000000 | L26: =SUMIF(고정형!$BF:$BF,'제품군별 SUMMARY'!$C26,고정형!AB:AB) | M26: =SUMIF(고정형!$BF:$BF,'제품군별 SUMMARY'!$C26,고정형!AC:AC)/1000000 | N26: =SUMIF(고정형!$BF:$BF,'제품군별 SUMMARY'!$C26,고정형!AE:AE) | O26: =SUMIF(고정형!$BF:$BF,'제품군별 SUMMARY'!$C26,고정형!AF:AF)/1000000 | P26: =SUMIF(고정형!$BF:$BF,'제품군별 SUMMARY'!$C26,고정형!AH:AH) | Q26: =SUMIF(고정형!$BF:$BF,'제품군별 SUMMARY'!$C26,고정형!AI:AI)/1000000 | R26: =SUMIF(고정형!$BF:$BF,'제품군별 SUMMARY'!$C26,고정형!AK:AK) | S26: =SUMIF(고정형!$BF:$BF,'제품군별 SUMMARY'!$C26,고정형!AL:AL)/1000000 | T26: =SUMIF(고정형!$BF:$BF,'제품군별 SUMMARY'!$C26,고정형!AN:AN) | U26: =SUMIF(고정형!$BF:$BF,'제품군별 SUMMARY'!$C26,고정형!AO:AO)/1000000 | V26: =SUMIF(고정형!$BF:$BF,'제품군별 SUMMARY'!$C26,고정형!AQ:AQ) | W26: =SUMIF(고정형!$BF:$BF,'제품군별 SUMMARY'!$C26,고정형!AR:AR)/1000000 | X26: =SUMIF(고정형!$BF:$BF,'제품군별 SUMMARY'!$C26,고정형!AT:AT) | Y26: =SUMIF(고정형!$BF:$BF,'제품군별 SUMMARY'!$C26,고정형!AU:AU)/1000000 | Z26: =SUMIF(고정형!$BF:$BF,'제품군별 SUMMARY'!$C26,고정형!AW:AW) | AA26: =SUMIF(고정형!$BF:$BF,'제품군별 SUMMARY'!$C26,고정형!AX:AX)/1000000
C27: LM | D27: =SUMIF(고정형!$BF:$BF,'제품군별 SUMMARY'!$C27,고정형!P:P) | E27: =SUMIF(고정형!$BF:$BF,'제품군별 SUMMARY'!$C27,고정형!Q:Q)/1000000 | F27: =SUMIF(고정형!$BF:$BF,'제품군별 SUMMARY'!$C27,고정형!S:S) | G27: =SUMIF(고정형!$BF:$BF,'제품군별 SUMMARY'!$C27,고정형!T:T)/1000000 | H27: =SUMIF(고정형!$BF:$BF,'제품군별 SUMMARY'!$C27,고정형!V:V) | I27: =SUMIF(고정형!$BF:$BF,'제품군별 SUMMARY'!$C27,고정형!W:W)/1000000 | J27: =SUMIF(고정형!$BF:$BF,'제품군별 SUMMARY'!$C27,고정형!Y:Y) | K27: =SUMIF(고정형!$BF:$BF,'제품군별 SUMMARY'!$C27,고정형!Z:Z)/1000000 | L27: =SUMIF(고정형!$BF:$BF,'제품군별 SUMMARY'!$C27,고정형!AB:AB) | M27: =SUMIF(고정형!$BF:$BF,'제품군별 SUMMARY'!$C27,고정형!AC:AC)/1000000 | N27: =SUMIF(고정형!$BF:$BF,'제품군별 SUMMARY'!$C27,고정형!AE:AE) | O27: =SUMIF(고정형!$BF:$BF,'제품군별 SUMMARY'!$C27,고정형!AF:AF)/1000000 | P27: =SUMIF(고정형!$BF:$BF,'제품군별 SUMMARY'!$C27,고정형!AH:AH) | Q27: =SUMIF(고정형!$BF:$BF,'제품군별 SUMMARY'!$C27,고정형!AI:AI)/1000000 | R27: =SUMIF(고정형!$BF:$BF,'제품군별 SUMMARY'!$C27,고정형!AK:AK) | S27: =SUMIF(고정형!$BF:$BF,'제품군별 SUMMARY'!$C27,고정형!AL:AL)/1000000 | T27: =SUMIF(고정형!$BF:$BF,'제품군별 SUMMARY'!$C27,고정형!AN:AN) | U27: =SUMIF(고정형!$BF:$BF,'제품군별 SUMMARY'!$C27,고정형!AO:AO)/1000000 | V27: =SUMIF(고정형!$BF:$BF,'제품군별 SUMMARY'!$C27,고정형!AQ:AQ) | W27: =SUMIF(고정형!$BF:$BF,'제품군별 SUMMARY'!$C27,고정형!AR:AR)/1000000 | X27: =SUMIF(고정형!$BF:$BF,'제품군별 SUMMARY'!$C27,고정형!AT:AT) | Y27: =SUMIF(고정형!$BF:$BF,'제품군별 SUMMARY'!$C27,고정형!AU:AU)/1000000 | Z27: =SUMIF(고정형!$BF:$BF,'제품군별 SUMMARY'!$C27,고정형!AW:AW) | AA27: =SUMIF(고정형!$BF:$BF,'제품군별 SUMMARY'!$C27,고정형!AX:AX)/1000000
C28: MSB 대형 | D28: =SUMIF(고정형!$BF:$BF,'제품군별 SUMMARY'!$C28,고정형!P:P) | E28: =SUMIF(고정형!$BF:$BF,'제품군별 SUMMARY'!$C28,고정형!Q:Q)/1000000 | F28: =SUMIF(고정형!$BF:$BF,'제품군별 SUMMARY'!$C28,고정형!S:S) | G28: =SUMIF(고정형!$BF:$BF,'제품군별 SUMMARY'!$C28,고정형!T:T)/1000000 | H28: =SUMIF(고정형!$BF:$BF,'제품군별 SUMMARY'!$C28,고정형!V:V) | I28: =SUMIF(고정형!$BF:$BF,'제품군별 SUMMARY'!$C28,고정형!W:W)/1000000 | J28: =SUMIF(고정형!$BF:$BF,'제품군별 SUMMARY'!$C28,고정형!Y:Y) | K28: =SUMIF(고정형!$BF:$BF,'제품군별 SUMMARY'!$C28,고정형!Z:Z)/1000000 | L28: =SUMIF(고정형!$BF:$BF,'제품군별 SUMMARY'!$C28,고정형!AB:AB) | M28: =SUMIF(고정형!$BF:$BF,'제품군별 SUMMARY'!$C28,고정형!AC:AC)/1000000 | N28: =SUMIF(고정형!$BF:$BF,'제품군별 SUMMARY'!$C28,고정형!AE:AE) | O28: =SUMIF(고정형!$BF:$BF,'제품군별 SUMMARY'!$C28,고정형!AF:AF)/1000000 | P28: =SUMIF(고정형!$BF:$BF,'제품군별 SUMMARY'!$C28,고정형!AH:AH) | Q28: =SUMIF(고정형!$BF:$BF,'제품군별 SUMMARY'!$C28,고정형!AI:AI)/1000000 | R28: =SUMIF(고정형!$BF:$BF,'제품군별 SUMMARY'!$C28,고정형!AK:AK) | S28: =SUMIF(고정형!$BF:$BF,'제품군별 SUMMARY'!$C28,고정형!AL:AL)/1000000 | T28: =SUMIF(고정형!$BF:$BF,'제품군별 SUMMARY'!$C28,고정형!AN:AN) | U28: =SUMIF(고정형!$BF:$BF,'제품군별 SUMMARY'!$C28,고정형!AO:AO)/1000000 | V28: =SUMIF(고정형!$BF:$BF,'제품군별 SUMMARY'!$C28,고정형!AQ:AQ) | W28: =SUMIF(고정형!$BF:$BF,'제품군별 SUMMARY'!$C28,고정형!AR:AR)/1000000 | X28: =SUMIF(고정형!$BF:$BF,'제품군별 SUMMARY'!$C28,고정형!AT:AT) | Y28: =SUMIF(고정형!$BF:$BF,'제품군별 SUMMARY'!$C28,고정형!AU:AU)/1000000 | Z28: =SUMIF(고정형!$BF:$BF,'제품군별 SUMMARY'!$C28,고정형!AW:AW) | AA28: =SUMIF(고정형!$BF:$BF,'제품군별 SUMMARY'!$C28,고정형!AX:AX)/1000000
C29: MSB 소형 | D29: =SUMIF(고정형!$BF:$BF,'제품군별 SUMMARY'!$C29,고정형!P:P) | E29: =SUMIF(고정형!$BF:$BF,'제품군별 SUMMARY'!$C29,고정형!Q:Q)/1000000 | F29: =SUMIF(고정형!$BF:$BF,'제품군별 SUMMARY'!$C29,고정형!S:S) | G29: =SUMIF(고정형!$BF:$BF,'제품군별 SUMMARY'!$C29,고정형!T:T)/1000000 | H29: =SUMIF(고정형!$BF:$BF,'제품군별 SUMMARY'!$C29,고정형!V:V) | I29: =SUMIF(고정형!$BF:$BF,'제품군별 SUMMARY'!$C29,고정형!W:W)/1000000 | J29: =SUMIF(고정형!$BF:$BF,'제품군별 SUMMARY'!$C29,고정형!Y:Y) | K29: =SUMIF(고정형!$BF:$BF,'제품군별 SUMMARY'!$C29,고정형!Z:Z)/1000000 | L29: =SUMIF(고정형!$BF:$BF,'제품군별 SUMMARY'!$C29,고정형!AB:AB) | M29: =SUMIF(고정형!$BF:$BF,'제품군별 SUMMARY'!$C29,고정형!AC:AC)/1000000 | N29: =SUMIF(고정형!$BF:$BF,'제품군별 SUMMARY'!$C29,고정형!AE:AE) | O29: =SUMIF(고정형!$BF:$BF,'제품군별 SUMMARY'!$C29,고정형!AF:AF)/1000000 | P29: =SUMIF(고정형!$BF:$BF,'제품군별 SUMMARY'!$C29,고정형!AH:AH) | Q29: =SUMIF(고정형!$BF:$BF,'제품군별 SUMMARY'!$C29,고정형!AI:AI)/1000000 | R29: =SUMIF(고정형!$BF:$BF,'제품군별 SUMMARY'!$C29,고정형!AK:AK) | S29: =SUMIF(고정형!$BF:$BF,'제품군별 SUMMARY'!$C29,고정형!AL:AL)/1000000 | T29: =SUMIF(고정형!$BF:$BF,'제품군별 SUMMARY'!$C29,고정형!AN:AN) | U29: =SUMIF(고정형!$BF:$BF,'제품군별 SUMMARY'!$C29,고정형!AO:AO)/1000000 | V29: =SUMIF(고정형!$BF:$BF,'제품군별 SUMMARY'!$C29,고정형!AQ:AQ) | W29: =SUMIF(고정형!$BF:$BF,'제품군별 SUMMARY'!$C29,고정형!AR:AR)/1000000 | X29: =SUMIF(고정형!$BF:$BF,'제품군별 SUMMARY'!$C29,고정형!AT:AT) | Y29: =SUMIF(고정형!$BF:$BF,'제품군별 SUMMARY'!$C29,고정형!AU:AU)/1000000 | Z29: =SUMIF(고정형!$BF:$BF,'제품군별 SUMMARY'!$C29,고정형!AW:AW) | AA29: =SUMIF(고정형!$BF:$BF,'제품군별 SUMMARY'!$C29,고정형!AX:AX)/1000000
C30: MSB 중형 | D30: =SUMIF(고정형!$BF:$BF,'제품군별 SUMMARY'!$C30,고정형!P:P) | E30: =SUMIF(고정형!$BF:$BF,'제품군별 SUMMARY'!$C30,고정형!Q:Q)/1000000 | F30: =SUMIF(고정형!$BF:$BF,'제품군별 SUMMARY'!$C30,고정형!S:S) | G30: =SUMIF(고정형!$BF:$BF,'제품군별 SUMMARY'!$C30,고정형!T:T)/1000000 | H30: =SUMIF(고정형!$BF:$BF,'제품군별 SUMMARY'!$C30,고정형!V:V) | I30: =SUMIF(고정형!$BF:$BF,'제품군별 SUMMARY'!$C30,고정형!W:W)/1000000 | J30: =SUMIF(고정형!$BF:$BF,'제품군별 SUMMARY'!$C30,고정형!Y:Y) | K30: =SUMIF(고정형!$BF:$BF,'제품군별 SUMMARY'!$C30,고정형!Z:Z)/1000000 | L30: =SUMIF(고정형!$BF:$BF,'제품군별 SUMMARY'!$C30,고정형!AB:AB) | M30: =SUMIF(고정형!$BF:$BF,'제품군별 SUMMARY'!$C30,고정형!AC:AC)/1000000 | N30: =SUMIF(고정형!$BF:$BF,'제품군별 SUMMARY'!$C30,고정형!AE:AE) | O30: =SUMIF(고정형!$BF:$BF,'제품군별 SUMMARY'!$C30,고정형!AF:AF)/1000000 | P30: =SUMIF(고정형!$BF:$BF,'제품군별 SUMMARY'!$C30,고정형!AH:AH) | Q30: =SUMIF(고정형!$BF:$BF,'제품군별 SUMMARY'!$C30,고정형!AI:AI)/1000000 | R30: =SUMIF(고정형!$BF:$BF,'제품군별 SUMMARY'!$C30,고정형!AK:AK) | S30: =SUMIF(고정형!$BF:$BF,'제품군별 SUMMARY'!$C30,고정형!AL:AL)/1000000 | T30: =SUMIF(고정형!$BF:$BF,'제품군별 SUMMARY'!$C30,고정형!AN:AN) | U30: =SUMIF(고정형!$BF:$BF,'제품군별 SUMMARY'!$C30,고정형!AO:AO)/1000000 | V30: =SUMIF(고정형!$BF:$BF,'제품군별 SUMMARY'!$C30,고정형!AQ:AQ) | W30: =SUMIF(고정형!$BF:$BF,'제품군별 SUMMARY'!$C30,고정형!AR:AR)/1000000 | X30: =SUMIF(고정형!$BF:$BF,'제품군별 SUMMARY'!$C30,고정형!AT:AT) | Y30: =SUMIF(고정형!$BF:$BF,'제품군별 SUMMARY'!$C30,고정형!AU:AU)/1000000 | Z30: =SUMIF(고정형!$BF:$BF,'제품군별 SUMMARY'!$C30,고정형!AW:AW) | AA30: =SUMIF(고정형!$BF:$BF,'제품군별 SUMMARY'!$C30,고정형!AX:AX)/1000000
C31: PS 소형 | D31: =SUMIF(고정형!$BF:$BF,'제품군별 SUMMARY'!$C31,고정형!P:P) | E31: =SUMIF(고정형!$BF:$BF,'제품군별 SUMMARY'!$C31,고정형!Q:Q)/1000000 | F31: =SUMIF(고정형!$BF:$BF,'제품군별 SUMMARY'!$C31,고정형!S:S) | G31: =SUMIF(고정형!$BF:$BF,'제품군별 SUMMARY'!$C31,고정형!T:T)/1000000 | H31: =SUMIF(고정형!$BF:$BF,'제품군별 SUMMARY'!$C31,고정형!V:V) | I31: =SUMIF(고정형!$BF:$BF,'제품군별 SUMMARY'!$C31,고정형!W:W)/1000000 | J31: =SUMIF(고정형!$BF:$BF,'제품군별 SUMMARY'!$C31,고정형!Y:Y) | K31: =SUMIF(고정형!$BF:$BF,'제품군별 SUMMARY'!$C31,고정형!Z:Z)/1000000 | L31: =SUMIF(고정형!$BF:$BF,'제품군별 SUMMARY'!$C31,고정형!AB:AB) | M31: =SUMIF(고정형!$BF:$BF,'제품군별 SUMMARY'!$C31,고정형!AC:AC)/1000000 | N31: =SUMIF(고정형!$BF:$BF,'제품군별 SUMMARY'!$C31,고정형!AE:AE) | O31: =SUMIF(고정형!$BF:$BF,'제품군별 SUMMARY'!$C31,고정형!AF:AF)/1000000 | P31: =SUMIF(고정형!$BF:$BF,'제품군별 SUMMARY'!$C31,고정형!AH:AH) | Q31: =SUMIF(고정형!$BF:$BF,'제품군별 SUMMARY'!$C31,고정형!AI:AI)/1000000 | R31: =SUMIF(고정형!$BF:$BF,'제품군별 SUMMARY'!$C31,고정형!AK:AK) | S31: =SUMIF(고정형!$BF:$BF,'제품군별 SUMMARY'!$C31,고정형!AL:AL)/1000000 | T31: =SUMIF(고정형!$BF:$BF,'제품군별 SUMMARY'!$C31,고정형!AN:AN) | U31: =SUMIF(고정형!$BF:$BF,'제품군별 SUMMARY'!$C31,고정형!AO:AO)/1000000 | V31: =SUMIF(고정형!$BF:$BF,'제품군별 SUMMARY'!$C31,고정형!AQ:AQ) | W31: =SUMIF(고정형!$BF:$BF,'제품군별 SUMMARY'!$C31,고정형!AR:AR)/1000000 | X31: =SUMIF(고정형!$BF:$BF,'제품군별 SUMMARY'!$C31,고정형!AT:AT) | Y31: =SUMIF(고정형!$BF:$BF,'제품군별 SUMMARY'!$C31,고정형!AU:AU)/1000000 | Z31: =SUMIF(고정형!$BF:$BF,'제품군별 SUMMARY'!$C31,고정형!AW:AW) | AA31: =SUMIF(고정형!$BF:$BF,'제품군별 SUMMARY'!$C31,고정형!AX:AX)/1000000
... C41: 산업용 기타 | D41: =SUMIF(고정형!$BF:$BF,'제품군별 SUMMARY'!$C41,고정형!P:P) | E41: =SUMIF(고정형!$BF:$BF,'제품군별 SUMMARY'!$C41,고정형!Q:Q)/1000000 | F41: =SUMIF(고정형!$BF:$BF,'제품군별 SUMMARY'!$C41,고정형!S:S) | G41: =SUMIF(고정형!$BF:$BF,'제품군별 SUMMARY'!$C41,고정형!T:T)/1000000 | H41: =SUMIF(고정형!$BF:$BF,'제품군별 SUMMARY'!$C41,고정형!V:V) | I41: =SUMIF(고정형!$BF:$BF,'제품군별 SUMMARY'!$C41,고정형!W:W)/1000000 | J41: =SUMIF(고정형!$BF:$BF,'제품군별 SUMMARY'!$C41,고정형!Y:Y) | K41: =SUMIF(고정형!$BF:$BF,'제품군별 SUMMARY'!$C41,고정형!Z:Z)/1000000 | L41: =SUMIF(고정형!$BF:$BF,'제품군별 SUMMARY'!$C41,고정형!AB:AB) | M41: =SUMIF(고정형!$BF:$BF,'제품군별 SUMMARY'!$C41,고정형!AC:AC)/1000000 | N41: =SUMIF(고정형!$BF:$BF,'제품군별 SUMMARY'!$C41,고정형!AE:AE) | O41: =SUMIF(고정형!$BF:$BF,'제품군별 SUMMARY'!$C41,고정형!AF:AF)/1000000 | P41: =SUMIF(고정형!$BF:$BF,'제품군별 SUMMARY'!$C41,고정형!AH:AH) | Q41: =SUMIF(고정형!$BF:$BF,'제품군별 SUMMARY'!$C41,고정형!AI:AI)/1000000 | R41: =SUMIF(고정형!$BF:$BF,'제품군별 SUMMARY'!$C41,고정형!AK:AK) | S41: =SUMIF(고정형!$BF:$BF,'제품군별 SUMMARY'!$C41,고정형!AL:AL)/1000000 | T41: =SUMIF(고정형!$BF:$BF,'제품군별 SUMMARY'!$C41,고정형!AN:AN) | U41: =SUMIF(고정형!$BF:$BF,'제품군별 SUMMARY'!$C41,고정형!AO:AO)/1000000 | V41: =SUMIF(고정형!$BF:$BF,'제품군별 SUMMARY'!$C41,고정형!AQ:AQ) | W41: =SUMIF(고정형!$BF:$BF,'제품군별 SUMMARY'!$C41,고정형!AR:AR)/1000000 | X41: =SUMIF(고정형!$BF:$BF,'제품군별 SUMMARY'!$C41,고정형!AT:AT) | Y41: =SUMIF(고정형!$BF:$BF,'제품군별 SUMMARY'!$C41,고정형!AU:AU)/1000000 | Z41: =SUMIF(고정형!$BF:$BF,'제품군별 SUMMARY'!$C41,고정형!AW:AW) | AA41: =SUMIF(고정형!$BF:$BF,'제품군별 SUMMARY'!$C41,고정형!AX:AX)/1000000
B42: 소계 | D42: =SUM(D19:D41) | E42: =SUM(E19:E41) | F42: =SUM(F19:F41) | G42: =SUM(G19:G41) | H42: =SUM(H19:H41) | I42: =SUM(I19:I41) | J42: =SUM(J19:J41) | K42: =SUM(K19:K41) | ... AA42: =SUM(AA19:AA41)
A43: 차량 부문 | B43: 차량대리점 | C43: AGM 3세대 | D43: =SUMIF(차량대리점!$BF:$BF,'제품군별 SUMMARY'!$C43,차량대리점!P:P) | E43: =SUMIF(차량대리점!$BF:$BF,'제품군별 SUMMARY'!$C43,차량대리점!Q:Q)/1000000 | F43: =SUMIF(차량대리점!$BF:$BF,'제품군별 SUMMARY'!$C43,차량대리점!S:S) | G43: =SUMIF(차량대리점!$BF:$BF,'제품군별 SUMMARY'!$C43,차량대리점!T:T)/1000000 | H43: =SUMIF(차량대리점!$BF:$BF,'제품군별 SUMMARY'!$C43,차량대리점!V:V) | I43: =SUMIF(차량대리점!$BF:$BF,'제품군별 SUMMARY'!$C43,차량대리점!W:W)/1000000 | J43: =SUMIF(차량대리점!$BF:$BF,'제품군별 SUMMARY'!$C43,차량대리점!Y:Y) | K43: =SUMIF(차량대리점!$BF:$BF,'제품군별 SUMMARY'!$C43,차량대리점!Z:Z)/1000000 | L43: =SUMIF(차량대리점!$BF:$BF,'제품군별 SUMMARY'!$C43,차량대리점!AB:AB) | M43: =SUMIF(차량대리점!$BF:$BF,'제품군별 SUMMARY'!$C43,차량대리점!AC:AC)/1000000 | N43: =SUMIF(차량대리점!$BF:$BF,'제품군별 SUMMARY'!$C43,차량대리점!AE:AE) | O43: =SUMIF(차량대리점!$BF:$BF,'제품군별 SUMMARY'!$C43,차량대리점!AF:AF)/1000000 | P43: =SUMIF(차량대리점!$BF:$BF,'제품군별 SUMMARY'!$C43,차량대리점!AH:AH) | Q43: =SUMIF(차량대리점!$BF:$BF,'제품군별 SUMMARY'!$C43,차량대리점!AI:AI)/1000000 | R43: =SUMIF(차량대리점!$BF:$BF,'제품군별 SUMMARY'!$C43,차량대리점!AK:AK) | S43: =SUMIF(차량대리점!$BF:$BF,'제품군별 SUMMARY'!$C43,차량대리점!AL:AL)/1000000 | T43: =SUMIF(차량대리점!$BF:$BF,'제품군별 SUMMARY'!$C43,차량대리점!AN:AN) | U43: =SUMIF(차량대리점!$BF:$BF,'제품군별 SUMMARY'!$C43,차량대리점!AO:AO)/1000000 | V43: =SUMIF(차량대리점!$BF:$BF,'제품군별 SUMMARY'!$C43,차량대리점!AQ:AQ) | W43: =SUMIF(차량대리점!$BF:$BF,'제품군별 SUMMARY'!$C43,차량대리점!AR:AR)/1000000 | X43: =SUMIF(차량대리점!$BF:$BF,'제품군별 SUMMARY'!$C43,차량대리점!AT:AT) | Y43: =SUMIF(차량대리점!$BF:$BF,'제품군별 SUMMARY'!$C43,차량대리점!AU:AU)/1000000 | Z43: =SUMIF(차량대리점!$BF:$BF,'제품군별 SUMMARY'!$C43,차량대리점!AW:AW) | AA43: =SUMIF(차량대리점!$BF:$BF,'제품군별 SUMMARY'!$C43,차량대리점!AX:AX)/1000000
C44: PT(CA) 대형 | D44: =SUMIF(차량대리점!$BF:$BF,'제품군별 SUMMARY'!$C44,차량대리점!P:P) | E44: =SUMIF(차량대리점!$BF:$BF,'제품군별 SUMMARY'!$C44,차량대리점!Q:Q)/1000000 | F44: =SUMIF(차량대리점!$BF:$BF,'제품군별 SUMMARY'!$C44,차량대리점!S:S) | G44: =SUMIF(차량대리점!$BF:$BF,'제품군별 SUMMARY'!$C44,차량대리점!T:T)/1000000 | H44: =SUMIF(차량대리점!$BF:$BF,'제품군별 SUMMARY'!$C44,차량대리점!V:V) | I44: =SUMIF(차량대리점!$BF:$BF,'제품군별 SUMMARY'!$C44,차량대리점!W:W)/1000000 | J44: =SUMIF(차량대리점!$BF:$BF,'제품군별 SUMMARY'!$C44,차량대리점!Y:Y) | K44: =SUMIF(차량대리점!$BF:$BF,'제품군별 SUMMARY'!$C44,차량대리점!Z:Z)/1000000 | L44: =SUMIF(차량대리점!$BF:$BF,'제품군별 SUMMARY'!$C44,차량대리점!AB:AB) | M44: =SUMIF(차량대리점!$BF:$BF,'제품군별 SUMMARY'!$C44,차량대리점!AC:AC)/1000000 | N44: =SUMIF(차량대리점!$BF:$BF,'제품군별 SUMMARY'!$C44,차량대리점!AE:AE) | O44: =SUMIF(차량대리점!$BF:$BF,'제품군별 SUMMARY'!$C44,차량대리점!AF:AF)/1000000 | P44: =SUMIF(차량대리점!$BF:$BF,'제품군별 SUMMARY'!$C44,차량대리점!AH:AH) | Q44: =SUMIF(차량대리점!$BF:$BF,'제품군별 SUMMARY'!$C44,차량대리점!AI:AI)/1000000 | R44: =SUMIF(차량대리점!$BF:$BF,'제품군별 SUMMARY'!$C44,차량대리점!AK:AK) | S44: =SUMIF(차량대리점!$BF:$BF,'제품군별 SUMMARY'!$C44,차량대리점!AL:AL)/1000000 | T44: =SUMIF(차량대리점!$BF:$BF,'제품군별 SUMMARY'!$C44,차량대리점!AN:AN) | U44: =SUMIF(차량대리점!$BF:$BF,'제품군별 SUMMARY'!$C44,차량대리점!AO:AO)/1000000 | V44: =SUMIF(차량대리점!$BF:$BF,'제품군별 SUMMARY'!$C44,차량대리점!AQ:AQ) | W44: =SUMIF(차량대리점!$BF:$BF,'제품군별 SUMMARY'!$C44,차량대리점!AR:AR)/1000000 | X44: =SUMIF(차량대리점!$BF:$BF,'제품군별 SUMMARY'!$C44,차량대리점!AT:AT) | Y44: =SUMIF(차량대리점!$BF:$BF,'제품군별 SUMMARY'!$C44,차량대리점!AU:AU)/1000000 | Z44: =SUMIF(차량대리점!$BF:$BF,'제품군별 SUMMARY'!$C44,차량대리점!AW:AW) | AA44: =SUMIF(차량대리점!$BF:$BF,'제품군별 SUMMARY'!$C44,차량대리점!AX:AX)/1000000
C45: MF 농기계 | D45: =SUMIF(차량대리점!$BF:$BF,'제품군별 SUMMARY'!$C45,차량대리점!P:P) | E45: =SUMIF(차량대리점!$BF:$BF,'제품군별 SUMMARY'!$C45,차량대리점!Q:Q)/1000000 | F45: =SUMIF(차량대리점!$BF:$BF,'제품군별 SUMMARY'!$C45,차량대리점!S:S) | G45: =SUMIF(차량대리점!$BF:$BF,'제품군별 SUMMARY'!$C45,차량대리점!T:T)/1000000 | H45: =SUMIF(차량대리점!$BF:$BF,'제품군별 SUMMARY'!$C45,차량대리점!V:V) | I45: =SUMIF(차량대리점!$BF:$BF,'제품군별 SUMMARY'!$C45,차량대리점!W:W)/1000000 | J45: =SUMIF(차량대리점!$BF:$BF,'제품군별 SUMMARY'!$C45,차량대리점!Y:Y) | K45: =SUMIF(차량대리점!$BF:$BF,'제품군별 SUMMARY'!$C45,차량대리점!Z:Z)/1000000 | L45: =SUMIF(차량대리점!$BF:$BF,'제품군별 SUMMARY'!$C45,차량대리점!AB:AB) | M45: =SUMIF(차량대리점!$BF:$BF,'제품군별 SUMMARY'!$C45,차량대리점!AC:AC)/1000000 | N45: =SUMIF(차량대리점!$BF:$BF,'제품군별 SUMMARY'!$C45,차량대리점!AE:AE) | O45: =SUMIF(차량대리점!$BF:$BF,'제품군별 SUMMARY'!$C45,차량대리점!AF:AF)/1000000 | P45: =SUMIF(차량대리점!$BF:$BF,'제품군별 SUMMARY'!$C45,차량대리점!AH:AH) | Q45: =SUMIF(차량대리점!$BF:$BF,'제품군별 SUMMARY'!$C45,차량대리점!AI:AI)/1000000 | R45: =SUMIF(차량대리점!$BF:$BF,'제품군별 SUMMARY'!$C45,차량대리점!AK:AK) | S45: =SUMIF(차량대리점!$BF:$BF,'제품군별 SUMMARY'!$C45,차량대리점!AL:AL)/1000000 | T45: =SUMIF(차량대리점!$BF:$BF,'제품군별 SUMMARY'!$C45,차량대리점!AN:AN) | U45: =SUMIF(차량대리점!$BF:$BF,'제품군별 SUMMARY'!$C45,차량대리점!AO:AO)/1000000 | V45: =SUMIF(차량대리점!$BF:$BF,'제품군별 SUMMARY'!$C45,차량대리점!AQ:AQ) | W45: =SUMIF(차량대리점!$BF:$BF,'제품군별 SUMMARY'!$C45,차량대리점!AR:AR)/1000000 | X45: =SUMIF(차량대리점!$BF:$BF,'제품군별 SUMMARY'!$C45,차량대리점!AT:AT) | Y45: =SUMIF(차량대리점!$BF:$BF,'제품군별 SUMMARY'!$C45,차량대리점!AU:AU)/1000000 | Z45: =SUMIF(차량대리점!$BF:$BF,'제품군별 SUMMARY'!$C45,차량대리점!AW:AW) | AA45: =SUMIF(차량대리점!$BF:$BF,'제품군별 SUMMARY'!$C45,차량대리점!AX:AX)/1000000
C46: GB 농기계 | D46: =SUMIF(차량대리점!$BF:$BF,'제품군별 SUMMARY'!$C46,차량대리점!P:P) | E46: =SUMIF(차량대리점!$BF:$BF,'제품군별 SUMMARY'!$C46,차량대리점!Q:Q)/1000000 | F46: =SUMIF(차량대리점!$BF:$BF,'제품군별 SUMMARY'!$C46,차량대리점!S:S) | G46: =SUMIF(차량대리점!$BF:$BF,'제품군별 SUMMARY'!$C46,차량대리점!T:T)/1000000 | H46: =SUMIF(차량대리점!$BF:$BF,'제품군별 SUMMARY'!$C46,차량대리점!V:V) | I46: =SUMIF(차량대리점!$BF:$BF,'제품군별 SUMMARY'!$C46,차량대리점!W:W)/1000000 | J46: =SUMIF(차량대리점!$BF:$BF,'제품군별 SUMMARY'!$C46,차량대리점!Y:Y) | K46: =SUMIF(차량대리점!$BF:$BF,'제품군별 SUMMARY'!$C46,차량대리점!Z:Z)/1000000 | L46: =SUMIF(차량대리점!$BF:$BF,'제품군별 SUMMARY'!$C46,차량대리점!AB:AB) | M46: =SUMIF(차량대리점!$BF:$BF,'제품군별 SUMMARY'!$C46,차량대리점!AC:AC)/1000000 | N46: =SUMIF(차량대리점!$BF:$BF,'제품군별 SUMMARY'!$C46,차량대리점!AE:AE) | O46: =SUMIF(차량대리점!$BF:$BF,'제품군별 SUMMARY'!$C46,차량대리점!AF:AF)/1000000 | P46: =SUMIF(차량대리점!$BF:$BF,'제품군별 SUMMARY'!$C46,차량대리점!AH:AH) | Q46: =SUMIF(차량대리점!$BF:$BF,'제품군별 SUMMARY'!$C46,차량대리점!AI:AI)/1000000 | R46: =SUMIF(차량대리점!$BF:$BF,'제품군별 SUMMARY'!$C46,차량대리점!AK:AK) | S46: =SUMIF(차량대리점!$BF:$BF,'제품군별 SUMMARY'!$C46,차량대리점!AL:AL)/1000000 | T46: =SUMIF(차량대리점!$BF:$BF,'제품군별 SUMMARY'!$C46,차량대리점!AN:AN) | U46: =SUMIF(차량대리점!$BF:$BF,'제품군별 SUMMARY'!$C46,차량대리점!AO:AO)/1000000 | V46: =SUMIF(차량대리점!$BF:$BF,'제품군별 SUMMARY'!$C46,차량대리점!AQ:AQ) | W46: =SUMIF(차량대리점!$BF:$BF,'제품군별 SUMMARY'!$C46,차량대리점!AR:AR)/1000000 | X46: =SUMIF(차량대리점!$BF:$BF,'제품군별 SUMMARY'!$C46,차량대리점!AT:AT) | Y46: =SUMIF(차량대리점!$BF:$BF,'제품군별 SUMMARY'!$C46,차량대리점!AU:AU)/1000000 | Z46: =SUMIF(차량대리점!$BF:$BF,'제품군별 SUMMARY'!$C46,차량대리점!AW:AW) | AA46: =SUMIF(차량대리점!$BF:$BF,'제품군별 SUMMARY'!$C46,차량대리점!AX:AX)/1000000
C47: FB | D47: =SUMIF(차량대리점!$BF:$BF,'제품군별 SUMMARY'!$C47,차량대리점!P:P) | E47: =SUMIF(차량대리점!$BF:$BF,'제품군별 SUMMARY'!$C47,차량대리점!Q:Q)/1000000 | F47: =SUMIF(차량대리점!$BF:$BF,'제품군별 SUMMARY'!$C47,차량대리점!S:S) | G47: =SUMIF(차량대리점!$BF:$BF,'제품군별 SUMMARY'!$C47,차량대리점!T:T)/1000000 | H47: =SUMIF(차량대리점!$BF:$BF,'제품군별 SUMMARY'!$C47,차량대리점!V:V) | I47: =SUMIF(차량대리점!$BF:$BF,'제품군별 SUMMARY'!$C47,차량대리점!W:W)/1000000 | J47: =SUMIF(차량대리점!$BF:$BF,'제품군별 SUMMARY'!$C47,차량대리점!Y:Y) | K47: =SUMIF(차량대리점!$BF:$BF,'제품군별 SUMMARY'!$C47,차량대리점!Z:Z)/1000000 | L47: =SUMIF(차량대리점!$BF:$BF,'제품군별 SUMMARY'!$C47,차량대리점!AB:AB) | M47: =SUMIF(차량대리점!$BF:$BF,'제품군별 SUMMARY'!$C47,차량대리점!AC:AC)/1000000 | N47: =SUMIF(차량대리점!$BF:$BF,'제품군별 SUMMARY'!$C47,차량대리점!AE:AE) | O47: =SUMIF(차량대리점!$BF:$BF,'제품군별 SUMMARY'!$C47,차량대리점!AF:AF)/1000000 | P47: =SUMIF(차량대리점!$BF:$BF,'제품군별 SUMMARY'!$C47,차량대리점!AH:AH) | Q47: =SUMIF(차량대리점!$BF:$BF,'제품군별 SUMMARY'!$C47,차량대리점!AI:AI)/1000000 | R47: =SUMIF(차량대리점!$BF:$BF,'제품군별 SUMMARY'!$C47,차량대리점!AK:AK) | S47: =SUMIF(차량대리점!$BF:$BF,'제품군별 SUMMARY'!$C47,차량대리점!AL:AL)/1000000 | T47: =SUMIF(차량대리점!$BF:$BF,'제품군별 SUMMARY'!$C47,차량대리점!AN:AN) | U47: =SUMIF(차량대리점!$BF:$BF,'제품군별 SUMMARY'!$C47,차량대리점!AO:AO)/1000000 | V47: =SUMIF(차량대리점!$BF:$BF,'제품군별 SUMMARY'!$C47,차량대리점!AQ:AQ) | W47: =SUMIF(차량대리점!$BF:$BF,'제품군별 SUMMARY'!$C47,차량대리점!AR:AR)/1000000 | X47: =SUMIF(차량대리점!$BF:$BF,'제품군별 SUMMARY'!$C47,차량대리점!AT:AT) | Y47: =SUMIF(차량대리점!$BF:$BF,'제품군별 SUMMARY'!$C47,차량대리점!AU:AU)/1000000 | Z47: =SUMIF(차량대리점!$BF:$BF,'제품군별 SUMMARY'!$C47,차량대리점!AW:AW) | AA47: =SUMIF(차량대리점!$BF:$BF,'제품군별 SUMMARY'!$C47,차량대리점!AX:AX)/1000000
C48: FS | D48: =SUMIF(차량대리점!$BF:$BF,'제품군별 SUMMARY'!$C48,차량대리점!P:P) | E48: =SUMIF(차량대리점!$BF:$BF,'제품군별 SUMMARY'!$C48,차량대리점!Q:Q)/1000000 | F48: =SUMIF(차량대리점!$BF:$BF,'제품군별 SUMMARY'!$C48,차량대리점!S:S) | G48: =SUMIF(차량대리점!$BF:$BF,'제품군별 SUMMARY'!$C48,차량대리점!T:T)/1000000 | H48: =SUMIF(차량대리점!$BF:$BF,'제품군별 SUMMARY'!$C48,차량대리점!V:V) | I48: =SUMIF(차량대리점!$BF:$BF,'제품군별 SUMMARY'!$C48,차량대리점!W:W)/1000000 | J48: =SUMIF(차량대리점!$BF:$BF,'제품군별 SUMMARY'!$C48,차량대리점!Y:Y) | K48: =SUMIF(차량대리점!$BF:$BF,'제품군별 SUMMARY'!$C48,차량대리점!Z:Z)/1000000 | L48: =SUMIF(차량대리점!$BF:$BF,'제품군별 SUMMARY'!$C48,차량대리점!AB:AB) | M48: =SUMIF(차량대리점!$BF:$BF,'제품군별 SUMMARY'!$C48,차량대리점!AC:AC)/1000000 | N48: =SUMIF(차량대리점!$BF:$BF,'제품군별 SUMMARY'!$C48,차량대리점!AE:AE) | O48: =SUMIF(차량대리점!$BF:$BF,'제품군별 SUMMARY'!$C48,차량대리점!AF:AF)/1000000 | P48: =SUMIF(차량대리점!$BF:$BF,'제품군별 SUMMARY'!$C48,차량대리점!AH:AH) | Q48: =SUMIF(차량대리점!$BF:$BF,'제품군별 SUMMARY'!$C48,차량대리점!AI:AI)/1000000 | R48: =SUMIF(차량대리점!$BF:$BF,'제품군별 SUMMARY'!$C48,차량대리점!AK:AK) | S48: =SUMIF(차량대리점!$BF:$BF,'제품군별 SUMMARY'!$C48,차량대리점!AL:AL)/1000000 | T48: =SUMIF(차량대리점!$BF:$BF,'제품군별 SUMMARY'!$C48,차량대리점!AN:AN) | U48: =SUMIF(차량대리점!$BF:$BF,'제품군별 SUMMARY'!$C48,차량대리점!AO:AO)/1000000 | V48: =SUMIF(차량대리점!$BF:$BF,'제품군별 SUMMARY'!$C48,차량대리점!AQ:AQ) | W48: =SUMIF(차량대리점!$BF:$BF,'제품군별 SUMMARY'!$C48,차량대리점!AR:AR)/1000000 | X48: =SUMIF(차량대리점!$BF:$BF,'제품군별 SUMMARY'!$C48,차량대리점!AT:AT) | Y48: =SUMIF(차량대리점!$BF:$BF,'제품군별 SUMMARY'!$C48,차량대리점!AU:AU)/1000000 | Z48: =SUMIF(차량대리점!$BF:$BF,'제품군별 SUMMARY'!$C48,차량대리점!AW:AW) | AA48: =SUMIF(차량대리점!$BF:$BF,'제품군별 SUMMARY'!$C48,차량대리점!AX:AX)/1000000
C49: GB 택시 EXP | D49: =SUMIF(차량대리점!$BF:$BF,'제품군별 SUMMARY'!$C49,차량대리점!P:P) | E49: =SUMIF(차량대리점!$BF:$BF,'제품군별 SUMMARY'!$C49,차량대리점!Q:Q)/1000000 | F49: =SUMIF(차량대리점!$BF:$BF,'제품군별 SUMMARY'!$C49,차량대리점!S:S) | G49: =SUMIF(차량대리점!$BF:$BF,'제품군별 SUMMARY'!$C49,차량대리점!T:T)/1000000 | H49: =SUMIF(차량대리점!$BF:$BF,'제품군별 SUMMARY'!$C49,차량대리점!V:V) | I49: =SUMIF(차량대리점!$BF:$BF,'제품군별 SUMMARY'!$C49,차량대리점!W:W)/1000000 | J49: =SUMIF(차량대리점!$BF:$BF,'제품군별 SUMMARY'!$C49,차량대리점!Y:Y) | K49: =SUMIF(차량대리점!$BF:$BF,'제품군별 SUMMARY'!$C49,차량대리점!Z:Z)/1000000 | L49: =SUMIF(차량대리점!$BF:$BF,'제품군별 SUMMARY'!$C49,차량대리점!AB:AB) | M49: =SUMIF(차량대리점!$BF:$BF,'제품군별 SUMMARY'!$C49,차량대리점!AC:AC)/1000000 | N49: =SUMIF(차량대리점!$BF:$BF,'제품군별 SUMMARY'!$C49,차량대리점!AE:AE) | O49: =SUMIF(차량대리점!$BF:$BF,'제품군별 SUMMARY'!$C49,차량대리점!AF:AF)/1000000 | P49: =SUMIF(차량대리점!$BF:$BF,'제품군별 SUMMARY'!$C49,차량대리점!AH:AH) | Q49: =SUMIF(차량대리점!$BF:$BF,'제품군별 SUMMARY'!$C49,차량대리점!AI:AI)/1000000 | R49: =SUMIF(차량대리점!$BF:$BF,'제품군별 SUMMARY'!$C49,차량대리점!AK:AK) | S49: =SUMIF(차량대리점!$BF:$BF,'제품군별 SUMMARY'!$C49,차량대리점!AL:AL)/1000000 | T49: =SUMIF(차량대리점!$BF:$BF,'제품군별 SUMMARY'!$C49,차량대리점!AN:AN) | U49: =SUMIF(차량대리점!$BF:$BF,'제품군별 SUMMARY'!$C49,차량대리점!AO:AO)/1000000 | V49: =SUMIF(차량대리점!$BF:$BF,'제품군별 SUMMARY'!$C49,차량대리점!AQ:AQ) | W49: =SUMIF(차량대리점!$BF:$BF,'제품군별 SUMMARY'!$C49,차량대리점!AR:AR)/1000000 | X49: =SUMIF(차량대리점!$BF:$BF,'제품군별 SUMMARY'!$C49,차량대리점!AT:AT) | Y49: =SUMIF(차량대리점!$BF:$BF,'제품군별 SUMMARY'!$C49,차량대리점!AU:AU)/1000000 | Z49: =SUMIF(차량대리점!$BF:$BF,'제품군별 SUMMARY'!$C49,차량대리점!AW:AW) | AA49: =SUMIF(차량대리점!$BF:$BF,'제품군별 SUMMARY'!$C49,차량대리점!AX:AX)/1000000
C50: MF 택시 EXP | D50: =SUMIF(차량대리점!$BF:$BF,'제품군별 SUMMARY'!$C50,차량대리점!P:P) | E50: =SUMIF(차량대리점!$BF:$BF,'제품군별 SUMMARY'!$C50,차량대리점!Q:Q)/1000000 | F50: =SUMIF(차량대리점!$BF:$BF,'제품군별 SUMMARY'!$C50,차량대리점!S:S) | G50: =SUMIF(차량대리점!$BF:$BF,'제품군별 SUMMARY'!$C50,차량대리점!T:T)/1000000 | H50: =SUMIF(차량대리점!$BF:$BF,'제품군별 SUMMARY'!$C50,차량대리점!V:V) | I50: =SUMIF(차량대리점!$BF:$BF,'제품군별 SUMMARY'!$C50,차량대리점!W:W)/1000000 | J50: =SUMIF(차량대리점!$BF:$BF,'제품군별 SUMMARY'!$C50,차량대리점!Y:Y) | K50: =SUMIF(차량대리점!$BF:$BF,'제품군별 SUMMARY'!$C50,차량대리점!Z:Z)/1000000 | L50: =SUMIF(차량대리점!$BF:$BF,'제품군별 SUMMARY'!$C50,차량대리점!AB:AB) | M50: =SUMIF(차량대리점!$BF:$BF,'제품군별 SUMMARY'!$C50,차량대리점!AC:AC)/1000000 | N50: =SUMIF(차량대리점!$BF:$BF,'제품군별 SUMMARY'!$C50,차량대리점!AE:AE) | O50: =SUMIF(차량대리점!$BF:$BF,'제품군별 SUMMARY'!$C50,차량대리점!AF:AF)/1000000 | P50: =SUMIF(차량대리점!$BF:$BF,'제품군별 SUMMARY'!$C50,차량대리점!AH:AH) | Q50: =SUMIF(차량대리점!$BF:$BF,'제품군별 SUMMARY'!$C50,차량대리점!AI:AI)/1000000 | R50: =SUMIF(차량대리점!$BF:$BF,'제품군별 SUMMARY'!$C50,차량대리점!AK:AK) | S50: =SUMIF(차량대리점!$BF:$BF,'제품군별 SUMMARY'!$C50,차량대리점!AL:AL)/1000000 | T50: =SUMIF(차량대리점!$BF:$BF,'제품군별 SUMMARY'!$C50,차량대리점!AN:AN) | U50: =SUMIF(차량대리점!$BF:$BF,'제품군별 SUMMARY'!$C50,차량대리점!AO:AO)/1000000 | V50: =SUMIF(차량대리점!$BF:$BF,'제품군별 SUMMARY'!$C50,차량대리점!AQ:AQ) | W50: =SUMIF(차량대리점!$BF:$BF,'제품군별 SUMMARY'!$C50,차량대리점!AR:AR)/1000000 | X50: =SUMIF(차량대리점!$BF:$BF,'제품군별 SUMMARY'!$C50,차량대리점!AT:AT) | Y50: =SUMIF(차량대리점!$BF:$BF,'제품군별 SUMMARY'!$C50,차량대리점!AU:AU)/1000000 | Z50: =SUMIF(차량대리점!$BF:$BF,'제품군별 SUMMARY'!$C50,차량대리점!AW:AW) | AA50: =SUMIF(차량대리점!$BF:$BF,'제품군별 SUMMARY'!$C50,차량대리점!AX:AX)/1000000
C51: 이륜용 상품 | D51: =SUMIF(차량대리점!$BF:$BF,'제품군별 SUMMARY'!$C51,차량대리점!P:P) | E51: =SUMIF(차량대리점!$BF:$BF,'제품군별 SUMMARY'!$C51,차량대리점!Q:Q)/1000000 | F51: =SUMIF(차량대리점!$BF:$BF,'제품군별 SUMMARY'!$C51,차량대리점!S:S) | G51: =SUMIF(차량대리점!$BF:$BF,'제품군별 SUMMARY'!$C51,차량대리점!T:T)/1000000 | H51: =SUMIF(차량대리점!$BF:$BF,'제품군별 SUMMARY'!$C51,차량대리점!V:V) | I51: =SUMIF(차량대리점!$BF:$BF,'제품군별 SUMMARY'!$C51,차량대리점!W:W)/1000000 | J51: =SUMIF(차량대리점!$BF:$BF,'제품군별 SUMMARY'!$C51,차량대리점!Y:Y) | K51: =SUMIF(차량대리점!$BF:$BF,'제품군별 SUMMARY'!$C51,차량대리점!Z:Z)/1000000 | L51: =SUMIF(차량대리점!$BF:$BF,'제품군별 SUMMARY'!$C51,차량대리점!AB:AB) | M51: =SUMIF(차량대리점!$BF:$BF,'제품군별 SUMMARY'!$C51,차량대리점!AC:AC)/1000000 | N51: =SUMIF(차량대리점!$BF:$BF,'제품군별 SUMMARY'!$C51,차량대리점!AE:AE) | O51: =SUMIF(차량대리점!$BF:$BF,'제품군별 SUMMARY'!$C51,차량대리점!AF:AF)/1000000 | P51: =SUMIF(차량대리점!$BF:$BF,'제품군별 SUMMARY'!$C51,차량대리점!AH:AH) | Q51: =SUMIF(차량대리점!$BF:$BF,'제품군별 SUMMARY'!$C51,차량대리점!AI:AI)/1000000 | R51: =SUMIF(차량대리점!$BF:$BF,'제품군별 SUMMARY'!$C51,차량대리점!AK:AK) | S51: =SUMIF(차량대리점!$BF:$BF,'제품군별 SUMMARY'!$C51,차량대리점!AL:AL)/1000000 | T51: =SUMIF(차량대리점!$BF:$BF,'제품군별 SUMMARY'!$C51,차량대리점!AN:AN) | U51: =SUMIF(차량대리점!$BF:$BF,'제품군별 SUMMARY'!$C51,차량대리점!AO:AO)/1000000 | V51: =SUMIF(차량대리점!$BF:$BF,'제품군별 SUMMARY'!$C51,차량대리점!AQ:AQ) | W51: =SUMIF(차량대리점!$BF:$BF,'제품군별 SUMMARY'!$C51,차량대리점!AR:AR)/1000000 | X51: =SUMIF(차량대리점!$BF:$BF,'제품군별 SUMMARY'!$C51,차량대리점!AT:AT) | Y51: =SUMIF(차량대리점!$BF:$BF,'제품군별 SUMMARY'!$C51,차량대리점!AU:AU)/1000000 | Z51: =SUMIF(차량대리점!$BF:$BF,'제품군별 SUMMARY'!$C51,차량대리점!AW:AW) | AA51: =SUMIF(차량대리점!$BF:$BF,'제품군별 SUMMARY'!$C51,차량대리점!AX:AX)/1000000
C52: 차량용 소형 EXP | D52: =SUMIF(차량대리점!$BF:$BF,'제품군별 SUMMARY'!$C52,차량대리점!P:P) | E52: =SUMIF(차량대리점!$BF:$BF,'제품군별 SUMMARY'!$C52,차량대리점!Q:Q)/1000000 | F52: =SUMIF(차량대리점!$BF:$BF,'제품군별 SUMMARY'!$C52,차량대리점!S:S) | G52: =SUMIF(차량대리점!$BF:$BF,'제품군별 SUMMARY'!$C52,차량대리점!T:T)/1000000 | H52: =SUMIF(차량대리점!$BF:$BF,'제품군별 SUMMARY'!$C52,차량대리점!V:V) | I52: =SUMIF(차량대리점!$BF:$BF,'제품군별 SUMMARY'!$C52,차량대리점!W:W)/1000000 | J52: =SUMIF(차량대리점!$BF:$BF,'제품군별 SUMMARY'!$C52,차량대리점!Y:Y) | K52: =SUMIF(차량대리점!$BF:$BF,'제품군별 SUMMARY'!$C52,차량대리점!Z:Z)/1000000 | L52: =SUMIF(차량대리점!$BF:$BF,'제품군별 SUMMARY'!$C52,차량대리점!AB:AB) | M52: =SUMIF(차량대리점!$BF:$BF,'제품군별 SUMMARY'!$C52,차량대리점!AC:AC)/1000000 | N52: =SUMIF(차량대리점!$BF:$BF,'제품군별 SUMMARY'!$C52,차량대리점!AE:AE) | O52: =SUMIF(차량대리점!$BF:$BF,'제품군별 SUMMARY'!$C52,차량대리점!AF:AF)/1000000 | P52: =SUMIF(차량대리점!$BF:$BF,'제품군별 SUMMARY'!$C52,차량대리점!AH:AH) | Q52: =SUMIF(차량대리점!$BF:$BF,'제품군별 SUMMARY'!$C52,차량대리점!AI:AI)/1000000 | R52: =SUMIF(차량대리점!$BF:$BF,'제품군별 SUMMARY'!$C52,차량대리점!AK:AK) | S52: =SUMIF(차량대리점!$BF:$BF,'제품군별 SUMMARY'!$C52,차량대리점!AL:AL)/1000000 | T52: =SUMIF(차량대리점!$BF:$BF,'제품군별 SUMMARY'!$C52,차량대리점!AN:AN) | U52: =SUMIF(차량대리점!$BF:$BF,'제품군별 SUMMARY'!$C52,차량대리점!AO:AO)/1000000 | V52: =SUMIF(차량대리점!$BF:$BF,'제품군별 SUMMARY'!$C52,차량대리점!AQ:AQ) | W52: =SUMIF(차량대리점!$BF:$BF,'제품군별 SUMMARY'!$C52,차량대리점!AR:AR)/1000000 | X52: =SUMIF(차량대리점!$BF:$BF,'제품군별 SUMMARY'!$C52,차량대리점!AT:AT) | Y52: =SUMIF(차량대리점!$BF:$BF,'제품군별 SUMMARY'!$C52,차량대리점!AU:AU)/1000000 | Z52: =SUMIF(차량대리점!$BF:$BF,'제품군별 SUMMARY'!$C52,차량대리점!AW:AW) | AA52: =SUMIF(차량대리점!$BF:$BF,'제품군별 SUMMARY'!$C52,차량대리점!AX:AX)/1000000
C53: 차량용 중형 EXP | D53: =SUMIF(차량대리점!$BF:$BF,'제품군별 SUMMARY'!$C53,차량대리점!P:P) | E53: =SUMIF(차량대리점!$BF:$BF,'제품군별 SUMMARY'!$C53,차량대리점!Q:Q)/1000000 | F53: =SUMIF(차량대리점!$BF:$BF,'제품군별 SUMMARY'!$C53,차량대리점!S:S) | G53: =SUMIF(차량대리점!$BF:$BF,'제품군별 SUMMARY'!$C53,차량대리점!T:T)/1000000 | H53: =SUMIF(차량대리점!$BF:$BF,'제품군별 SUMMARY'!$C53,차량대리점!V:V) | I53: =SUMIF(차량대리점!$BF:$BF,'제품군별 SUMMARY'!$C53,차량대리점!W:W)/1000000 | J53: =SUMIF(차량대리점!$BF:$BF,'제품군별 SUMMARY'!$C53,차량대리점!Y:Y) | K53: =SUMIF(차량대리점!$BF:$BF,'제품군별 SUMMARY'!$C53,차량대리점!Z:Z)/1000000 | L53: =SUMIF(차량대리점!$BF:$BF,'제품군별 SUMMARY'!$C53,차량대리점!AB:AB) | M53: =SUMIF(차량대리점!$BF:$BF,'제품군별 SUMMARY'!$C53,차량대리점!AC:AC)/1000000 | N53: =SUMIF(차량대리점!$BF:$BF,'제품군별 SUMMARY'!$C53,차량대리점!AE:AE) | O53: =SUMIF(차량대리점!$BF:$BF,'제품군별 SUMMARY'!$C53,차량대리점!AF:AF)/1000000 | P53: =SUMIF(차량대리점!$BF:$BF,'제품군별 SUMMARY'!$C53,차량대리점!AH:AH) | Q53: =SUMIF(차량대리점!$BF:$BF,'제품군별 SUMMARY'!$C53,차량대리점!AI:AI)/1000000 | R53: =SUMIF(차량대리점!$BF:$BF,'제품군별 SUMMARY'!$C53,차량대리점!AK:AK) | S53: =SUMIF(차량대리점!$BF:$BF,'제품군별 SUMMARY'!$C53,차량대리점!AL:AL)/1000000 | T53: =SUMIF(차량대리점!$BF:$BF,'제품군별 SUMMARY'!$C53,차량대리점!AN:AN) | U53: =SUMIF(차량대리점!$BF:$BF,'제품군별 SUMMARY'!$C53,차량대리점!AO:AO)/1000000 | V53: =SUMIF(차량대리점!$BF:$BF,'제품군별 SUMMARY'!$C53,차량대리점!AQ:AQ) | W53: =SUMIF(차량대리점!$BF:$BF,'제품군별 SUMMARY'!$C53,차량대리점!AR:AR)/1000000 | X53: =SUMIF(차량대리점!$BF:$BF,'제품군별 SUMMARY'!$C53,차량대리점!AT:AT) | Y53: =SUMIF(차량대리점!$BF:$BF,'제품군별 SUMMARY'!$C53,차량대리점!AU:AU)/1000000 | Z53: =SUMIF(차량대리점!$BF:$BF,'제품군별 SUMMARY'!$C53,차량대리점!AW:AW) | AA53: =SUMIF(차량대리점!$BF:$BF,'제품군별 SUMMARY'!$C53,차량대리점!AX:AX)/1000000
...

Sheet 고정형
A2: 2026년 산전 고정형 판매계획 (더미데이터)
A6: 1. 기본정보
A7: 구분 | B7: 25년 8월 누계 | C7: 26년 경영계획 | D7: 증감율
A8: LME | B8: 2055.77 | C8: 1810 | D8: =C8/B8-1
A9: USD | B9: 1355.01 | C9: 1344.64 | D9: =C9/B9-1
A10: 지수 | B10: =B8*B9/1000 | C10: =C8*C9/1000 | D10: =C10/B10-1 | I10: ※ 더미데이터 안내
A11: JPY | B11: 1010.47 | C11: 1001.5 | D11: =C11/B11-1 | I11: - 본 파일은 판매계획 양식.xlsx의 스키마(시트/컬럼/수식 구조)를 참고하여 생성한 가상 데이터입니다.
A12: EUR | B12: 1633.83 | C12: 1513.04 | D12: =C12/B12-1 | I12: - 거래처명, 담당자명, 코드, 수량/금액은 전부 무작위로 생성된 값이며 실제 데이터와 무관합니다.
A15: 2026년 판매계획 (더미데이터) - 담당/거래처/수량/금액은 모두 가상 값
A16: 구분 | L16: 25년 8월 누계 | O16: 1월 | R16: 2월 | U16: 3월 | X16: 4월 | AA16: 5월 | AD16: 6월 | AG16: 7월 | AJ16: 8월 | AM16: 9월 | AP16: 10월 | AS16: 11월 | AV16: 12월
A17: 담당 | B17: 팀 | C17: 유통채널 | D17: 고객 | E17: 고객명 | F17: 납품처 | G17: 납품처명 | H17: 영업담당 | I17: 구분 | J17: 제품군 구분 | K17: 제품코드 | L17: 판가 | M17: 수량 | N17: 금액 | O17: 1월 판가 | P17: 1월 수량 | Q17: 1월 금액 | R17: 2월 판가 | S17: 2월 수량 | T17: 2월 금액 | U17: 3월 판가 | V17: 3월 수량 | W17: 3월 금액 | X17: 4월 판가 | Y17: 4월 수량 | Z17: 4월 금액 | AA17: 5월 판가 | AB17: 5월 수량 | AC17: 5월 금액 | AD17: 6월 판가 | AE17: 6월 수량 | AF17: 6월 금액 | AG17: 7월 판가 | AH17: 7월 수량 | AI17: 7월 금액 | AJ17: 8월 판가 | AK17: 8월 수량 | AL17: 8월 금액 | AM17: 9월 판가 | AN17: 9월 수량 | AO17: 9월 금액 | AP17: 10월 판가 | AQ17: 10월 수량 | AR17: 10월 금액 | AS17: 11월 판가 | AT17: 11월 수량 | AU17: 11월 금액 | AV17: 12월 판가 | AW17: 12월 수량 | AX17: 12월 금액 | AY17: 연평균판가 | AZ17: 연간수량합계 | BA17: 연간금액합계 | BB17: 판가차이 | BC17: 차이율 | BD17: 비고 | BF17: 본부보고용(제품군 매핑)
A18: 산전 영업부문 | B18: 산전 고정형 | C18: =D18&J18 | D18: 9078908 | E18: 참좋은상사D | F18: 9078908 | G18: 참좋은상사D | H18: 윤재원 | I18: 상품 | J18: LM | L18: 243781.98 | M18: 63 | N18: =L18*M18 | O18: 256400.49 | P18: 50 | Q18: =O18*P18 | R18: 240008.94 | S18: 55 | T18: =R18*S18 | U18: 229901.71 | V18: 73 | W18: =U18*V18 | X18: 224387.19 | Y18: 58 | Z18: =X18*Y18 | AA18: 236906.32 | AB18: 57 | AC18: =AA18*AB18 | AD18: 232300.87 | AE18: 46 | AF18: =AD18*AE18 | AG18: 241803.68 | AH18: 49 | AI18: =AG18*AH18 | AJ18: 264371.58 | AK18: 47 | AL18: =AJ18*AK18 | AM18: 233698.1 | AN18: 68 | AO18: =AM18*AN18 | AP18: 262575.22 | AQ18: 58 | AR18: =AP18*AQ18 | AS18: 228779.08 | AT18: 47 | AU18: =AS18*AT18 | AV18: 251644.6 | AW18: 73 | AX18: =AV18*AW18 | AY18: =IFERROR(BA18/AZ18,0) | AZ18: =SUM(P18,S18,V18,Y18,AB18,AE18,AH18,AK18,AN18,AQ18,AT18,AW18) | BA18: =SUM(Q18,T18,W18,Z18,AC18,AF18,AI18,AL18,AO18,AR18,AU18,AX18) | BB18: =AY18-L18 | BC18: =IFERROR(BB18/L18,0) | BF18: =VLOOKUP("고정형"&J18,인자!A:D,4,0)
A19: 산전 영업부문 | B19: 산전 고정형 | C19: =D19&J19 | D19: 9012281 | E19: 가상상사B | F19: 9012281 | G19: 가상상사B | H19: 권나윤 | I19: 광주 | J19: ES 소형 | L19: 117137.24 | M19: 3724 | N19: =L19*M19 | O19: 120315.98 | P19: 3422 | Q19: =O19*P19 | R19: 114095.91 | S19: 3075 | T19: =R19*S19 | U19: 111678.13 | V19: 4700 | W19: =U19*V19 | X19: 120605.33 | Y19: 3968 | Z19: =X19*Y19 | AA19: 109432.86 | AB19: 4236 | AC19: =AA19*AB19 | AD19: 109251.62 | AE19: 3455 | AF19: =AD19*AE19 | AG19: 128605.52 | AH19: 4037 | AI19: =AG19*AH19 | AJ19: 118471.43 | AK19: 4137 | AL19: =AJ19*AK19 | AM19: 125169.39 | AN19: 4341 | AO19: =AM19*AN19 | AP19: 110789.53 | AQ19: 2679 | AR19: =AP19*AQ19 | AS19: 112813.78 | AT19: 3205 | AU19: =AS19*AT19 | AV19: 110366.31 | AW19: 4714 | AX19: =AV19*AW19 | AY19: =IFERROR(BA19/AZ19,0) | AZ19: =SUM(P19,S19,V19,Y19,AB19,AE19,AH19,AK19,AN19,AQ19,AT19,AW19) | BA19: =SUM(Q19,T19,W19,Z19,AC19,AF19,AI19,AL19,AO19,AR19,AU19,AX19) | BB19: =AY19-L19 | BC19: =IFERROR(BB19/L19,0) | BF19: =VLOOKUP("고정형"&J19,인자!A:D,4,0)
A20: 산전 영업부문 | B20: 산전 고정형 | C20: =D20&J20 | D20: 9093851 | E20: 한빛파워F | F20: 9093851 | G20: 한빛파워F | H20: 최지우 | I20: 상품 | J20: RP 대형 | L20: 121711.41 | M20: 3768 | N20: =L20*M20 | O20: 113018.09 | P20: 2953 | Q20: =O20*P20 | R20: 127675 | S20: 3856 | T20: =R20*S20 | U20: 127724.29 | V20: 3606 | W20: =U20*V20 | X20: 123744.79 | Y20: 3456 | Z20: =X20*Y20 | AA20: 133817.45 | AB20: 2950 | AC20: =AA20*AB20 | AD20: 121553.57 | AE20: 4346 | AF20: =AD20*AE20 | AG20: 130501.48 | AH20: 2983 | AI20: =AG20*AH20 | AJ20: 113434.6 | AK20: 4176 | AL20: =AJ20*AK20 | AM20: 124058.23 | AN20: 3507 | AO20: =AM20*AN20 | AP20: 124045.55 | AQ20: 3696 | AR20: =AP20*AQ20 | AS20: 115660.26 | AT20: 3888 | AU20: =AS20*AT20 | AV20: 132481.19 | AW20: 4176 | AX20: =AV20*AW20 | AY20: =IFERROR(BA20/AZ20,0) | AZ20: =SUM(P20,S20,V20,Y20,AB20,AE20,AH20,AK20,AN20,AQ20,AT20,AW20) | BA20: =SUM(Q20,T20,W20,Z20,AC20,AF20,AI20,AL20,AO20,AR20,AU20,AX20) | BB20: =AY20-L20 | BC20: =IFERROR(BB20/L20,0) | BF20: =VLOOKUP("고정형"&J20,인자!A:D,4,0)
A21: 산전 영업부문 | B21: 산전 고정형 | C21: =D21&J21 | D21: 9012281 | E21: 가상상사B | F21: 9012281 | G21: 가상상사B | H21: 한지호 | I21: 상품 | J21: LM | L21: 231736.63 | M21: 2796 | N21: =L21*M21 | O21: 213733.11 | P21: 2687 | Q21: =O21*P21 | R21: 229591.85 | S21: 3557 | T21: =R21*S21 | U21: 249156.41 | V21: 2399 | W21: =U21*V21 | X21: 231763.79 | Y21: 2257 | Z21: =X21*Y21 | AA21: 250860.83 | AB21: 3418 | AC21: =AA21*AB21 | AD21: 222395.09 | AE21: 3029 | AF21: =AD21*AE21 | AG21: 236787.11 | AH21: 2214 | AI21: =AG21*AH21 | AJ21: 243903.3 | AK21: 2862 | AL21: =AJ21*AK21 | AM21: 244650.22 | AN21: 2847 | AO21: =AM21*AN21 | AP21: 208589.47 | AQ21: 2501 | AR21: =AP21*AQ21 | AS21: 209465.66 | AT21: 3516 | AU21: =AS21*AT21 | AV21: 249289.38 | AW21: 3352 | AX21: =AV21*AW21 | AY21: =IFERROR(BA21/AZ21,0) | AZ21: =SUM(P21,S21,V21,Y21,AB21,AE21,AH21,AK21,AN21,AQ21,AT21,AW21) | BA21: =SUM(Q21,T21,W21,Z21,AC21,AF21,AI21,AL21,AO21,AR21,AU21,AX21) | BB21: =AY21-L21 | BC21: =IFERROR(BB21/L21,0) | BF21: =VLOOKUP("고정형"&J21,인자!A:D,4,0)
A22: 산전 영업부문 | B22: 산전 고정형 | C22: =D22&J22 | D22: 9073564 | E22: 가상상사E | F22: 9073564 | G22: 가상상사E | H22: 최지우 | I22: 광주 | J22: GSL 중형 | L22: 264012.83 | M22: 655 | N22: =L22*M22 | O22: 242134.27 | P22: 649 | Q22: =O22*P22 | R22: 241266.15 | S22: 757 | T22: =R22*S22 | U22: 278049.57 | V22: 509 | W22: =U22*V22 | X22: 262707.68 | Y22: 675 | Z22: =X22*Y22 | AA22: 251607.22 | AB22: 801 | AC22: =AA22*AB22 | AD22: 259954.32 | AE22: 542 | AF22: =AD22*AE22 | AG22: 266087.76 | AH22: 745 | AI22: =AG22*AH22 | AJ22: 248232.84 | AK22: 581 | AL22: =AJ22*AK22 | AM22: 290157.99 | AN22: 714 | AO22: =AM22*AN22 | AP22: 260744.36 | AQ22: 662 | AR22: =AP22*AQ22 | AS22: 244000.88 | AT22: 547 | AU22: =AS22*AT22 | AV22: 255463.33 | AW22: 690 | AX22: =AV22*AW22 | AY22: =IFERROR(BA22/AZ22,0) | AZ22: =SUM(P22,S22,V22,Y22,AB22,AE22,AH22,AK22,AN22,AQ22,AT22,AW22) | BA22: =SUM(Q22,T22,W22,Z22,AC22,AF22,AI22,AL22,AO22,AR22,AU22,AX22) | BB22: =AY22-L22 | BC22: =IFERROR(BB22/L22,0) | BF22: =VLOOKUP("고정형"&J22,인자!A:D,4,0)
A23: 산전 영업부문 | B23: 산전 고정형 | C23: =D23&J23 | D23: 9078908 | E23: 참좋은상사D | F23: 9078908 | G23: 참좋은상사D | H23: 임도현 | I23: 광주 | J23: CGS 소형 | L23: 25942.96 | M23: 492 | N23: =L23*M23 | O23: 24536.55 | P23: 612 | Q23: =O23*P23 | R23: 27808.96 | S23: 365 | T23: =R23*S23 | U23: 24583.57 | V23: 542 | W23: =U23*V23 | X23: 24460.25 | Y23: 383 | Z23: =X23*Y23 | AA23: 28202.67 | AB23: 513 | AC23: =AA23*AB23 | AD23: 25801.16 | AE23: 576 | AF23: =AD23*AE23 | AG23: 27538.44 | AH23: 401 | AI23: =AG23*AH23 | AJ23: 23851.6 | AK23: 472 | AL23: =AJ23*AK23 | AM23: 25546.44 | AN23: 482 | AO23: =AM23*AN23 | AP23: 27131.54 | AQ23: 543 | AR23: =AP23*AQ23 | AS23: 28455.1 | AT23: 373 | AU23: =AS23*AT23 | AV23: 25437.7 | AW23: 445 | AX23: =AV23*AW23 | AY23: =IFERROR(BA23/AZ23,0) | AZ23: =SUM(P23,S23,V23,Y23,AB23,AE23,AH23,AK23,AN23,AQ23,AT23,AW23) | BA23: =SUM(Q23,T23,W23,Z23,AC23,AF23,AI23,AL23,AO23,AR23,AU23,AX23) | BB23: =AY23-L23 | BC23: =IFERROR(BB23/L23,0) | BF23: =VLOOKUP("고정형"&J23,인자!A:D,4,0)
